Workbook
Name ASPECTO: [1]DATOS!$DP$1098:$DP$1102
Name ASPECTO: [1]DATOS!$DP$1098:$DP$1102
Name ASPECTO: [2]DATOS!$DP$1098:$DP$1102
Name B: [3]DATOS!$DF$3005:$DF$3008
Name COLOR: [1]DATOS!$DO$1098:$DO$1109
Name COLOR: [1]DATOS!$DO$1098:$DO$1109
Name COLOR: [2]DATOS!$DO$1098:$DO$1109
Name ESPUMA: [1]DATOS!$DU$1098:$DU$1099
Name ESPUMA: [1]DATOS!$DU$1098:$DU$1099
Name ESPUMA: [2]DATOS!$DU$1098:$DU$1099
Name GENERO: [3]DATOS!$H$3005:$H$3006
Name OLOR: [1]DATOS!$DQ$1098:$DQ$1101
Name OLOR: [1]DATOS!$DQ$1098:$DQ$1101
Name OLOR: [2]DATOS!$DQ$1098:$DQ$1101
Name P: DATOS!#REF!
Name P: DATOS!#REF!
Name PROT: [1]DATOS!$DW$1098:$DW$1103
Name PROT: [1]DATOS!$DW$1098:$DW$1103
Name PROT: [2]DATOS!$DW$1098:$DW$1103
Name REACCION: [1]DATOS!$DS$1098:$DS$1100
Name REACCION: [1]DATOS!$DS$1098:$DS$1100
Name REACCION: [2]DATOS!$DS$1098:$DS$1100
Name REACCION: [3]DATOS!$CS$3005:$CS$3007
Name RESPON: [4]DATOS!$FL$3006:$FL$3013
Name RESPONSABLE: DATOS!#REF!
Name RESPONSABLE: [1]DATOS!$Q$1098:$Q$1105
Name RESPONSABLE: DATOS!#REF!
Name RESPONSABLE: DATOS!#REF!
Name RESPONSABLE: DATOS!#REF!
Name RESPONSABLE: [1]DATOS!$Q$1098:$Q$1105
Name RESPONSABLE: DATOS!#REF!
Name RESPONSABLE: [2]DATOS!$Q$1098:$Q$1105
Name RESPONSABLE: DATOS!#REF!
Name RESPONSABLE: DATOS!#REF!
Name RESPONSABLE: DATOS!#REF!
Name RESPONSABLE: DATOS!#REF!
Name RESPONSABLES: [3]DATOS!$AQ$3005:$AQ$3012
Name U: ESPERMATO!$F$44
Name U: #REF!
Name U: LIQUIDOS!$E$41
Name U: #REF!
Name U: #REF!

Sheet HEMATO
S1: 12
D2: =LOOKUP(S1,DATOS!A:A,DATOS!R:R) -> 0 | J2: =LOOKUP(S1,DATOS!A:A,DATOS!B:B) -> 12 | L2: N° de Asegurado: | Q2: =LOOKUP(S1,DATOS!A:A,DATOS!J:J) -> 890805 CCH
L4: Cod. Asegurado: | P4: =LOOKUP(S1,DATOS!A:A,DATOS!K:K) -> 50 | R4: Edad: | S4: =LOOKUP(S1,DATOS!A:A,DATOS!H:H) -> 35 | T4: AÑOS
C5: =LOOKUP(S1,DATOS!A:A,DATOS!N:N) -> DRA. CHAMBI | H5: PAISE EL ALTO | K5: =LOOKUP(S1,DATOS!A:A,DATOS!G:G) -> TORREZ VARGAS DELIA
C6: Medico Solicitante | H6: Centro Asistencial | L6: Nombre y Apellidos
C8: =LOOKUP(S1,DATOS!A:A,DATOS!L:L) -> PAISE EL ALTO | H8: =LOOKUP(S1,DATOS!A:A,DATOS!M:M) -> GINECOLOGIA | K8: =LOOKUP(S1,DATOS!A:A,DATOS!O:O) -> 46141
C9: Policlinico o Servicio | G9: Consultorio | L9: Fecha de Solicitud
I10: HEMATOLOGIA
C11: Globulos Rojos: | D11: =D12*107000 -> 4922000 | E11: Ul | I11: Globulos Blancos: | J11: =LOOKUP(S1,DATOS!A:A,DATOS!Z:Z) -> 8430 | K11: uL | O11: Plaquetas | R11: =LOOKUP(S1,DATOS!A:A,DATOS!AJ:AJ) -> 215000 | T11: Ul
C12: Hematocrito | D12: =LOOKUP(S1,DATOS!A:A,DATOS!U:U) -> 46 | E12: % | H12: Formula Diferencial | J12: % | K12: uL | O12: T. de Protrombina | R12: =LOOKUP(S1,DATOS!A:A,DATOS!AV:AV) -> 12 | T12: seg.
C13: Hemoglobina | D13: =LOOKUP(S1,DATOS!A:A,DATOS!V:V) -> 14.7 | E13: g/dL | H13: Mielocitos | J13: =LOOKUP(S1,DATOS!A:A,DATOS!AF:AF) -> 0 | K13: =J13*J11/100 -> 0 | O13: Actividad | R13: =LOOKUP(S1,DATOS!A:A,DATOS!AW:AW) -> 100 | T13: %
C14: Reticulocitos | D14: =LOOKUP(S1,DATOS!A:A,DATOS!AL:AL) -> 0 | E14: % | H14: Metamielocitos | J14: =LOOKUP(S1,DATOS!A:A,DATOS!AG:AG) -> 0 | K14: =J14*J11/100 -> 0 | O14: INR | R14: =LOOKUP(S1,DATOS!A:A,DATOS!AX:AX) -> 1
C15: Eritrosedimentacion | D15: =LOOKUP(S1,DATOS!A:A,DATOS!AM:AM) -> 63 | E15: 1ra. Hr | H15: Cayados | J15: =LOOKUP(S1,DATOS!A:A,DATOS!AE:AE) -> 0 | K15: =J15*J11/100 -> 0 | O15: T. de Sangria | R15: =LOOKUP(S1,DATOS!A:A,DATOS!AR:AR) -> - | S15: min | T15: =LOOKUP(S1,DATOS!A:A,DATOS!AS:AS) -> - | U15: seg
H16: Segmentados | J16: =LOOKUP(S1,DATOS!A:A,DATOS!AA:AA) -> 78 | K16: =J16*J11/100 -> 6575.4 | O16: T. de Coagulacion | R16: =LOOKUP(S1,DATOS!A:A,DATOS!AT:AT) -> - | S16: min | T16: =LOOKUP(S1,DATOS!A:A,DATOS!AU:AU) -> - | U16: seg
C17: Grupo sanguineo | D17: =LOOKUP(S1,DATOS!A:A,DATOS!AK:AK) -> 0 | I17: Eosinofilos | J17: =LOOKUP(S1,DATOS!A:A,DATOS!AD:AD) -> 2 | K17: =J17*J11/100 -> 168.6
C18: VES 2 HORA: | D18: =LOOKUP(S1,DATOS!A:A,DATOS!AN:AN) -> 0 | I18: Basófilos | J18: =LOOKUP(S1,DATOS!A:A,DATOS!AH:AH) -> 0 | K18: =J18*J11/100 -> 0 | O18: Observaciones: | R18: =LOOKUP(S1,DATOS!A:A,DATOS!BB:BB) -> 0
C19: INDICE DE KATZ: | D19: =LOOKUP(S1,DATOS!A:A,DATOS!AQ:AQ) | H19: Linfocitos | J19: =LOOKUP(S1,DATOS!A:A,DATOS!AB:AB) -> 19 | K19: =J19*J11/100 -> 1601.7
H20: Monocitos | J20: =LOOKUP(S1,DATOS!A:A,DATOS!AC:AC) -> 1 | K20: =J20*J11/100 -> 84.3
H21: TOTAL | J21: =LOOKUP(S1,DATOS!A:A,DATOS!AI:AI) -> 100 | K21: =SUM(K13:K20) -> 8430
C23: Comentario Serie Roja: | D23: =LOOKUP(S1,DATOS!A:A,DATOS!AY:AY) -> 0
C24: Comentario Serie Blanca: | D24: =LOOKUP(S1,DATOS!A:A,DATOS!AZ:AZ) -> 0
C25: Comentario Plaquetas: | D25: =LOOKUP(S1,DATOS!A:A,DATOS!BA:BA) -> 0
C27: Elaborado por: Anahi Vigabriel C. | F27: Fecha de Reporte: | J27: =LOOKUP(S1,DATOS!A:A,DATOS!P:P) -> 46156 | R27: Hrs. | S27: =NOW() -> 46197.396

Sheet G. SANGUINEO
Q1: 1
M2: N° de Asegurado: | P2: =LOOKUP(Q1,DATOS!A:A,DATOS!J:J) -> 530421 SSA
J3: =LOOKUP(Q1,DATOS!A:A,DATOS!B:B) -> 1 | N3: Cod. Beneficiario: | P3: =LOOKUP(Q1,DATOS!A:A,DATOS!K:K) -> ID | Q3: Edad | R3: =LOOKUP(Q1,DATOS!A:A,DATOS!H:H) -> 72
C5: =LOOKUP(Q1,DATOS!A:A,DATOS!N:N) -> DR. ZAMBRANA | H5: PAISE EL ALTO | L5: =LOOKUP(Q1,DATOS!A:A,DATOS!G:G) -> SIRPA SIRPA ANCELMO
C6: Medico Solicitante | H6: Centro Asistencial | L6: Nombres y Apellidos
C8: =LOOKUP(Q1,DATOS!A:A,DATOS!L:L) -> PAISE EL ALTO | G8: =LOOKUP(Q1,DATOS!A:A,DATOS!M:M) -> CARDIOLOGIA | L8: =LOOKUP(Q1,DATOS!A:A,DATOS!O:O) -> 46108
C9: Policlinico o Servicio | G9: Consultorio | L9: Fecha de Solicitud
G11: HEMATOLOGIA
F14: GRUPO SANGUINEO: | K14: =LOOKUP(Q1,DATOS!A:A,DATOS!AK:AK) -> 0
B21: Elaborado por: Anahi Vigabriel C. | G21: Fecha de Reporte: | I21: =LOOKUP(Q1,DATOS!A:A,DATOS!P:P) -> 46156 | P21: Hrs: | Q21: =NOW() -> 46197.396

Sheet ---TP---
Q1: 1
M2: N° de Asegurado: | P2: =LOOKUP(Q1,DATOS!A:A,DATOS!J:J) -> 530421 SSA
J3: =LOOKUP(Q1,DATOS!A:A,DATOS!B:B) -> 1 | N3: Cod. Beneficiario: | P3: =LOOKUP(Q1,DATOS!A:A,DATOS!K:K) -> ID | Q3: Edad | R3: =LOOKUP(Q1,DATOS!A:A,DATOS!H:H) -> 72
C5: =LOOKUP(Q1,DATOS!A:A,DATOS!N:N) -> DR. ZAMBRANA | H5: PAISE EL ALTO | L5: =LOOKUP(Q1,DATOS!A:A,DATOS!G:G) -> SIRPA SIRPA ANCELMO
C6: Medico Solicitante | H6: Centro Asistencial | L6: Nombres y Apellidos
C8: =LOOKUP(Q1,DATOS!A:A,DATOS!L:L) -> PAISE EL ALTO | G8: =LOOKUP(Q1,DATOS!A:A,DATOS!M:M) -> CARDIOLOGIA | L8: =LOOKUP(Q1,DATOS!A:A,DATOS!O:O) -> 46108
C9: Policlinico o Servicio | G9: Consultorio | L9: Fecha de Solicitud
G11: HEMATOLOGIA
F14: TIEMPO DE PROTROMBINA: | K14: =LOOKUP(Q1,DATOS!A:A,DATOS!AV:AV) -> 12 | M14: Seg.
H15: ACTIVIDAD: | K15: =LOOKUP(Q1,DATOS!A:A,DATOS!AW:AW) -> 100 | M15: %
H16: INR: | K16: =LOOKUP(Q1,DATOS!A:A,DATOS!AX:AX) -> 1
F17: Tiempo de Coagulacion: | K17: =LOOKUP(Q1,DATOS!A:A,DATOS!AT:AT) -> - | M17: min | N17: =LOOKUP(Q1,DATOS!A:A,DATOS!AU:AU) -> - | P17: seg
F18: Tiempo de Sangria: | K18: =LOOKUP(Q1,DATOS!A:A,DATOS!AR:AR) -> - | M18: min | N18: =LOOKUP(Q1,DATOS!A:A,DATOS!AS:AS) -> - | P18: seg
B21: Elaborado por: Anahi Vigabriel C. | G21: Fecha de Reporte: | I21: =LOOKUP(Q1,DATOS!A:A,DATOS!P:P) -> 46156 | P21: Hrs: | Q21: =NOW() -> 46197.396

Sheet QMC 
Q1: 15
C2: =LOOKUP(Q1,DATOS!A:A,DATOS!R:R) -> 0 | J2: =LOOKUP(Q1,DATOS!A:A,DATOS!B:B) -> 15 | M2: N° de Asegurado: | P2: =LOOKUP(Q1,DATOS!A:A,DATOS!J:J) -> 810101 YCA
N3: Cod. Asegurado: | P3: =LOOKUP(Q1,DATOS!A:A,DATOS!K:K) -> ID | Q3: Edad: | R3: =LOOKUP(Q1,DATOS!A:A,DATOS!H:H) -> 45
C5: =LOOKUP(Q1,DATOS!A:A,DATOS!N:N) -> DR. CHAVARRIA | H5: PAISE EL ALTO | L5: =LOOKUP(Q1,DATOS!A:A,DATOS!G:G) -> YUJRA CACHI ALEJANDRO
C6: Medico Solicitante | H6: Centro Asistencial | L6: Nombres y Apellidos
C8: =LOOKUP(Q1,DATOS!A:A,DATOS!L:L) -> PAISE EL ALTO | G8: =LOOKUP(Q1,DATOS!A:A,DATOS!M:M) -> REUMATOLOGIA | L8: =LOOKUP(Q1,DATOS!A:A,DATOS!O:O) -> 46105
C9: Policlinico o Servicio | G9: Consultorio | L9: Fecha de Solicitud
H10: QUIMICA SANGUINEA
E11: GLICEMIA | F11: =LOOKUP(Q1,DATOS!A:A,DATOS!BC:BC) -> 94 | G11: mg/dl | H11: (70 - 110) | M11: COLESTEROL | N11: =LOOKUP(Q1,DATOS!A:A,DATOS!BI:BI) -> 0 | O11: mg/dl | P11: (120-190)
E12: Hb GLICOSILADA | F12: =LOOKUP(Q1,DATOS!A:A,DATOS!BH:BH) -> 0 | G12: % | H12: (4 - 6) | M12: TRIGLICERID. | N12: =LOOKUP(Q1,DATOS!A:A,DATOS!BJ:BJ) -> 0 | O12: mg/dl | P12: (60-150)
E13: NUS | F13: =LOOKUP(Q1,DATOS!A:A,DATOS!BF:BF) | G13: mg/dl | H13: (7 - 21) | M13: HDL | N13: =LOOKUP(Q1,DATOS!A:A,DATOS!BK:BK) -> 0 | O13: mg/dl | P13: (>55)
E14: UREA | F14: =LOOKUP(Q1,DATOS!A:A,DATOS!BE:BE) -> 0 | G14: mg/dl | H14: (15 - 45) | M14: LDL | N14: =LOOKUP(Q1,DATOS!A:A,DATOS!BL:BL) | O14: mg/dl | P14: (<150)
E15: CREATININA | F15: =LOOKUP(Q1,DATOS!A:A,DATOS!BD:BD) -> 1.4 | G15: mg/dl | H15: (0.4 - 1.4) | M15: VLDL | N15: =LOOKUP(Q1,DATOS!A:A,DATOS!BM:BM) | O15: mg/dl
E16: ACIDO URICO | F16: =LOOKUP(Q1,DATOS!A:A,DATOS!BG:BG) -> 5.1 | G16: mg/dl | H16: (2.4 - 7.0) | M16: T.G.O. | N16: =LOOKUP(Q1,DATOS!A:A,DATOS!BN:BN) -> 31 | O16: U/l | P16: (10-39)
E17: AMILASA | F17: =LOOKUP(Q1,DATOS!A:A,DATOS!BX:BX) -> 0 | G17: U/l | H17: (<125) | M17: T.G.P. | N17: =LOOKUP(Q1,DATOS!A:A,DATOS!BO:BO) -> 43 | O17: U/l | P17: (10-37)
E18: PROTEINAS TOTALES | F18: =LOOKUP(Q1,DATOS!A:A,DATOS!BT:BT) -> 0 | G18: g/dl | H18: (6.4 - 8.3) | M18: PAL | N18: =LOOKUP(Q1,DATOS!A:A,DATOS!BP:BP) -> 0 | O18: U/l | P18: (hasta 115)
E19: ALBUMINA | F19: =LOOKUP(Q1,DATOS!A:A,DATOS!BU:BU) -> 4.2 | G19: g/dl | H19: (3.5 - 5.0) | M19: BIL. DIRECTA | N19: =LOOKUP(Q1,DATOS!A:A,DATOS!BQ:BQ) -> 0 | O19: mg/dl | P19: (hasta 0.3)
M20: BIL. INDIRECTA | N20: =LOOKUP(Q1,DATOS!A:A,DATOS!BR:BR) -> 0 | O20: mg/dl | P20: (hasta 0.7)
E21: NOTA | F21: =LOOKUP(Q1,DATOS!A:A,DATOS!CE:CE) -> FOSFATA ALCALINA NHR | M21: BIL. TOTAL | N21: =LOOKUP(Q1,DATOS!A:A,DATOS!BS:BS) | O21: mg/dl | P21: (hasta 1)
B23: Elaborado por: Anahi Vigabriel C. | G23: Fecha de Reporte: | I23: =LOOKUP(Q1,DATOS!A:A,DATOS!P:P) -> 46156 | P23: Hrs: | Q23: =NOW() -> 46197.396

Sheet ELEC. MICRO. PROT
Q1: 6
C2: =LOOKUP(Q1,DATOS!A:A,DATOS!R:R) -> 0 | J2: =LOOKUP(Q1,DATOS!A:A,DATOS!B:B) -> 6 | M2: N° de Asegurado: | P2: =LOOKUP(Q1,DATOS!A:A,DATOS!J:J) -> 770729 CTF
N3: Cod. Beneficiario: | P3: =LOOKUP(Q1,DATOS!A:A,DATOS!K:K) -> 50 | Q3: Edad | R3: =LOOKUP(Q1,DATOS!A:A,DATOS!H:H) -> 45
C6: =LOOKUP(Q1,DATOS!A:A,DATOS!N:N) -> DR. TARIFA | H6: PAISE EL ALTO | L6: =LOOKUP(Q1,DATOS!A:A,DATOS!G:G) -> MAMANI CANAVIRI ROSMERY
C7: Medico Solicitante | H7: Centro Asistencial | L7: Nombres y Apellidos
C9: =LOOKUP(Q1,DATOS!A:A,DATOS!L:L) -> PAISE EL ALTO | G9: =LOOKUP(Q1,DATOS!A:A,DATOS!M:M) -> NEUMOLOGIA | L9: =LOOKUP(Q1,DATOS!A:A,DATOS!O:O) -> 46154
C10: Policlinico o Servicio | G10: Consultorio | L10: Fecha de Solicitud
B12: ELECTROLITOS | M12: VOLUMEN 24 Hrs. | N12: =LOOKUP(Q1,DATOS!A:A,DATOS!CD:CD) -> 0 | P12: ml/dia
E13: SODIO | F13: =LOOKUP(Q1,DATOS!A:A,DATOS!BY:BY) -> 143.7 | G13: mmol/L | H13: (135,0 – 148,0) | M13: CREATININA EN ORINA | N13: =LOOKUP(Q1,DATOS!A:A,DATOS!CC:CC) -> 0 | P13: mg/día
E14: POTASIO | F14: =LOOKUP(Q1,DATOS!A:A,DATOS!BZ:BZ) -> 3.53 | G14: mmol/L | H14: (3,50 – 5,30) | M14: PROTEINAS EN ORINA | N14: =LOOKUP(Q1,DATOS!A:A,DATOS!CB:CB) -> 0 | P14: mg/día | Q14: (28 - 140)
E15: CLORO | F15: =LOOKUP(Q1,DATOS!A:A,DATOS!CA:CA) -> 113 | G15: mmol/L | H15: (98 – 107,0)
D17: MICROALBUMINURIA: | J17: =LOOKUP(Q1,DATOS!A:A,DATOS!CS:CS) -> 0
B22: Elaborado por: Anahi Vigabriel C. | G22: Fecha de Reporte: | I22: =LOOKUP(Q1,DATOS!A:A,DATOS!P:P) -> 46156 | P22: Hrs: | Q22: =NOW() -> 46197.396

Sheet SERO
Q1: 12
C2: =LOOKUP(Q1,DATOS!A:A,DATOS!R:R) -> 0 | I2: =LOOKUP(Q1,DATOS!A:A,DATOS!B:B) -> 12 | M2: N° de Asegurado: | P2: =LOOKUP(Q1,DATOS!A:A,DATOS!J:J) -> 890805 CCH
N3: Cod. Asegurado: | P3: =LOOKUP(Q1,DATOS!A:A,DATOS!K:K) -> 50 | Q3: Edad | R3: =LOOKUP(Q1,DATOS!A:A,DATOS!H:H) -> 35
C6: =LOOKUP(Q1,DATOS!A:A,DATOS!N:N) -> DRA. CHAMBI | H6: PAISE EL ALTO | L6: =LOOKUP(Q1,DATOS!A:A,DATOS!G:G) -> TORREZ VARGAS DELIA
C7: Medico Solicitante | H7: Centro Asistencial | L7: Nombres y Apellidos
C9: =LOOKUP(Q1,DATOS!A:A,DATOS!L:L) -> PAISE EL ALTO | G9: =LOOKUP(Q1,DATOS!A:A,DATOS!M:M) -> GINECOLOGIA | K9: =LOOKUP(Q1,DATOS!A:A,DATOS!O:O) -> 46141
C10: Policlinico o Servicio | G10: Consultorio | L10: Fecha de Solicitud
D12: P.C.R. | E12: =LOOKUP(Q1,DATOS!A:A,DATOS!CF:CF) -> 1.6 | G12: mg/dL | H12: (<0,8) | M12: TEST DE EMBARAZO: | N12: =LOOKUP(Q1,DATOS!A:A,DATOS!CJ:CJ) -> 0
D13: LATEX | E13: =LOOKUP(Q1,DATOS!A:A,DATOS!CG:CG) -> 0 | G13: UI/ml | H13: (<8) | M13: V.I.H.: | N13: =LOOKUP(Q1,DATOS!A:A,DATOS!CI:CI) -> 0
D14: ASTO | E14: =LOOKUP(Q1,DATOS!A:A,DATOS!CH:CH) -> 0 | G14: UI/ml | H14: (hasta 200) | M14: PSA PRUEBA RAPIDA | N14: =LOOKUP(Q1,DATOS!A:A,DATOS!CL:CL) -> 0
D15: R.P.R. | E15: =LOOKUP(Q1,DATOS!A:A,DATOS!CK:CK) -> 0 | M15: H. PYLORI EN SUERO: | N15: =LOOKUP(Q1,DATOS!A:A,DATOS!CM:CM) -> 0
D16: WIDAL: | M16: HEPATITIS B: | N16: =LOOKUP(Q1,DATOS!A:A,DATOS!CN:CN) -> 0
D17: EBERTH O | E17: =LOOKUP(Q1,DATOS!A:A,DATOS!CO:CO) -> -
D18: EBERTH H | E18: =LOOKUP(Q1,DATOS!A:A,DATOS!CP:CP) -> -
D19: PARATIPHY A | E19: =LOOKUP(Q1,DATOS!A:A,DATOS!CQ:CQ) -> -
D20: PARATIPHY B | E20: =LOOKUP(Q1,DATOS!A:A,DATOS!CR:CR) -> -
B22: Elaborado por: Anahi Vigabriel C. | G22: Fecha de Reporte: | I22: =LOOKUP(Q1,DATOS!A:A,DATOS!P:P) -> 46156 | P22: Hrs: | Q22: =NOW() -> 46197.396

Sheet EGO
S1: 12
C2: DX: | E2: =LOOKUP(S1,DATOS!A:A,DATOS!R:R) -> 0 | I2: =LOOKUP(S1,DATOS!A:A,DATOS!A:A) -> 12 | O2: N° de Asegurado: | R2: =LOOKUP(S1,DATOS!A:A,DATOS!J:J) -> 890805 CCH | W2: EXAMEN:
W3: =[5]HEMATO!R1 -> 53
O4: Cod. Asegurado: | R4: =LOOKUP(S1,DATOS!A:A,DATOS!K:K) -> 50 | S4: Edad: | T4: =LOOKUP(S1,DATOS!A:A,DATOS!H:H) -> 35
C6: =LOOKUP(S1,DATOS!A:A,DATOS!N:N) -> DRA. CHAMBI | I6: PAISE EL ALTO | N6: =LOOKUP(S1,DATOS!A:A,DATOS!G:G) -> TORREZ VARGAS DELIA
C7: Medico Solicitante | H7: Centro Asistencial | O7: Nombre y Apellidos
C9: =LOOKUP(S1,DATOS!A:A,DATOS!L:L) -> PAISE EL ALTO | H9: =LOOKUP(S1,DATOS!A:A,DATOS!M:M) -> GINECOLOGIA | M9: =LOOKUP(S1,DATOS!A:A,DATOS!O:O) -> 46141
C10: Policlinico o Servicio | I10: Consultorio | O10: Fecha de Solicitud
F11: EXAMEN GENERAL DE ORINA
B12: Cantidad: | D12: =LOOKUP(S1,DATOS!A:A,DATOS!CV:CV) -> 80 | F12: ml | I12: Densidad: | J12: =LOOKUP(S1,DATOS!A:A,DATOS!DC:DC) -> 1020 | L12: EXAMEN MICROSCOPICO (por campo)
B13: Color: | D13: =LOOKUP(S1,DATOS!A:A,DATOS!CW:CW) -> Amarillo | I13: pH: | J13: =LOOKUP(S1,DATOS!A:A,DATOS!DD:DD) -> 6.5 | M13: Cel. Epitelia.: | O13: =LOOKUP(S1,DATOS!A:A,DATOS!DO:DO) -> 7-15XC | R13: Cilindros:
B14: Olor: | D14: =LOOKUP(S1,DATOS!A:A,DATOS!CX:CX) -> Sui Generis | I14: Proteinas: | J14: =LOOKUP(S1,DATOS!A:A,DATOS!DE:DE) -> No Cont. | M14: Leucocitos: | O14: =LOOKUP(S1,DATOS!A:A,DATOS!DM:DM) -> 8-7XC | R14: Hialinos: | S14: =LOOKUP(S1,DATOS!A:A,DATOS!DT:DT) -> 0
B15: Aspecto: | D15: =LOOKUP(S1,DATOS!A:A,DATOS!CY:CY) -> Lig. Opalescente | I15: Glucosa: | J15: =LOOKUP(S1,DATOS!A:A,DATOS!DF:DF) -> No Cont. | M15: Hematies: | O15: =LOOKUP(S1,DATOS!A:A,DATOS!DN:DN) -> 0 | R15: Granulosos: | S15: =LOOKUP(S1,DATOS!A:A,DATOS!DU:DU) -> 0
B16: Espuma: | D16: =LOOKUP(S1,DATOS!A:A,DATOS!CZ:CZ) -> Fugaz | I16: Cetonas: | J16: =LOOKUP(S1,DATOS!A:A,DATOS!DG:DG) -> No Cont. | M16: Bacterias: | O16: =LOOKUP(S1,DATOS!A:A,DATOS!DP:DP) -> AUMENTADAS | R16: Hematicos: | S16: =LOOKUP(S1,DATOS!A:A,DATOS!DV:DV) -> 0
B17: Otros | D17: =LOOKUP(S1,DATOS!A:A,DATOS!DA:DA) -> 0 | I17: Bilirrubinas: | J17: =LOOKUP(S1,DATOS!A:A,DATOS!DH:DH) -> No Cont. | M17: Cel. Renales: | O17: =LOOKUP(S1,DATOS!A:A,DATOS!DQ:DQ) -> 0-1XC | R17: Pigmentarios:
B18: Sedimento: | D18: =LOOKUP(S1,DATOS!A:A,DATOS!DB:DB) -> 0 | I18: Sangre: | J18: =LOOKUP(S1,DATOS!A:A,DATOS!DI:DI) -> No Cont. | M18: Fil. Mucoso: | O18: =LOOKUP(S1,DATOS!A:A,DATOS!DR:DR) -> 0 | R18: Cereos: | S18: =LOOKUP(S1,DATOS!A:A,DATOS!DW:DW) -> 0
I19: Urobilinogeno: | J19: =LOOKUP(S1,DATOS!A:A,DATOS!DJ:DJ) -> Normal | M19: Piocitos: | O19: =LOOKUP(S1,DATOS!A:A,DATOS!DL:DL) -> 0
I20: Nitritos: | J20: =LOOKUP(S1,DATOS!A:A,DATOS!DK:DK) -> Negativo | M20: Cristales: | O20: =LOOKUP(S1,DATOS!A:A,DATOS!DS:DS) -> 0
B22: Otros: | G22: =LOOKUP(S1,DATOS!A:A,DATOS!DX:DX) -> 0
B23: Observaciones 1: | G23: =LOOKUP(S1,DATOS!A:A,DATOS!DY:DY) -> 0
B24: Observaciones 2: | G24: =LOOKUP(S1,DATOS!A:A,DATOS!DZ:DZ) -> 0
B25: Elaborado por: Anahi Vigabriel C. | F25: Fecha de Reporte: | J25: =LOOKUP(S1,DATOS!A:A,DATOS!P:P) -> 46156 | R25: Hrs: | S25: =NOW() -> 46197.396

Sheet TOLER
Q1: 12
C2: =LOOKUP(Q1,DATOS!A:A,DATOS!R:R) -> 0 | J2: =LOOKUP(Q1,DATOS!A:A,DATOS!B:B) -> 12 | M2: N° de Asegurado: | P2: =LOOKUP(Q1,DATOS!A:A,DATOS!J:J) -> 890805 CCH
N3: Cod. Asegurado: | P3: =LOOKUP(Q1,DATOS!A:A,DATOS!K:K) -> 50 | Q3: Edad: | R3: =LOOKUP(Q1,DATOS!A:A,DATOS!H:H) -> 35
C6: =LOOKUP(Q1,DATOS!A:A,DATOS!N:N) -> DRA. CHAMBI | H6: PAISE EL ALTO | L6: =LOOKUP(Q1,DATOS!A:A,DATOS!G:G) -> TORREZ VARGAS DELIA
C7: Medico Solicitante | H7: Centro Asistencial | L7: Nombre y Apellidos
C9: =LOOKUP(Q1,DATOS!A:A,DATOS!L:L) -> PAISE EL ALTO | G9: =LOOKUP(Q1,DATOS!A:A,DATOS!M:M) -> GINECOLOGIA | L9: =LOOKUP(Q1,DATOS!A:A,DATOS!O:O) -> 46141
C10: Policlinico o Servicio | G10: Consultorio | L10: Fecha de Solicitud
G13: TOLERANCIA A LA GLUCOSA
I15: Hora | K15: RESULTADO
H16: BASAL | I16: =LOOKUP(Q1,DATOS!A:A,DATOS!EZ:EZ) -> 0 | K16: =LOOKUP(Q1,DATOS!A:A,DATOS!EY:EY) -> 0 | M16: mg/dl
H17: 60’ | I17: =LOOKUP(Q1,DATOS!A:A,DATOS!FB:FB) -> 0 | J17: 0.39236111 | K17: =LOOKUP(Q1,DATOS!A:A,DATOS!FA:FA) -> 0 | M17: mg/dl
H18: 120’ | I18: =LOOKUP(Q1,DATOS!A:A,DATOS!FD:FD) -> 0 | J18: 0.43402778 | K18: =LOOKUP(Q1,DATOS!A:A,DATOS!FC:FC) -> 0 | M18: mg/dl
B23: Elaborado por: Anahi Vigabriel C. | G23: Fecha de Reporte: | I23: =LOOKUP(Q1,DATOS!A:A,DATOS!P:P) -> 46156 | P23: Hrs: | Q23: =NOW() -> 46197.396

Sheet HTO-HB
Q1: 10
M2: N° de Asegurado: | P2: =LOOKUP(Q1,DATOS!A:A,DATOS!J:J) -> 850501 CAO
J3: =LOOKUP(Q1,DATOS!A:A,DATOS!B:B) -> 10 | N3: Cod. Beneficiario: | P3: =LOOKUP(Q1,DATOS!A:A,DATOS!K:K) -> ID | Q3: Edad: | R3: =LOOKUP(Q1,DATOS!A:A,DATOS!H:H) -> 41
C5: =LOOKUP(Q1,DATOS!A:A,DATOS!N:N) -> DR. AGUAYO | H5: PAISE EL ALTO | L5: =LOOKUP(Q1,DATOS!A:A,DATOS!G:G) -> CONTRERAS ALI OVIDIO
C6: Medico Solicitante | H6: Centro Asistencial | L6: Nombre y Apellidos
C8: =LOOKUP(Q1,DATOS!A:A,DATOS!L:L) -> PAISE EL ALTO | G8: =LOOKUP(Q1,DATOS!A:A,DATOS!M:M) -> C-45 | L8: =LOOKUP(Q1,DATOS!A:A,DATOS!O:O) -> 46155
C9: Policlinico o Servicio | G9: Consultorio | L9: Fecha de Solicitud
G11: HEMATOLOGIA
H14: HEMATOCRITO: | K14: =LOOKUP(Q1,DATOS!A:A,DATOS!U:U) -> 64 | M14: %
H15: HEMOGLOBINA: | K15: =LOOKUP(Q1,DATOS!A:A,DATOS!V:V) -> 21 | M15: g/dL
B21: Elaborado por: Anahi Vigabriel C. | G21: Fecha de Reporte: | I21: =LOOKUP(Q1,DATOS!A:A,DATOS!P:P) -> 46156 | P21: Hrs: | Q21: =NOW() -> 46197.396

Sheet HTO-HB -LEUCO+WIDAL
Q1: 11
M2: N° de Asegurado: | P2: =LOOKUP(Q1,DATOS!A:A,DATOS!J:J) -> 570805 CHA
J3: =LOOKUP(Q1,DATOS!A:A,DATOS!B:B) -> 11 | N3: Cod. Beneficiario: | P3: =LOOKUP(Q1,DATOS!A:A,DATOS!K:K) -> ID | Q3: Edad: | R3: =LOOKUP(Q1,DATOS!A:A,DATOS!H:H) -> 68
C5: =LOOKUP(Q1,DATOS!A:A,DATOS!N:N) -> DR. ZAMBRANA | H5: PAISE EL ALTO | L5: =LOOKUP(Q1,DATOS!A:A,DATOS!G:G) -> CHURA HUACOTO ANGELINO
C6: Medico Solicitante | H6: Centro Asistencial | L6: Nombres y Apellidos
C7: =LOOKUP(Q1,DATOS!A:A,DATOS!L:L) -> PAISE EL ALTO | G7: =LOOKUP(Q1,DATOS!A:A,DATOS!M:M) -> CARDIOLOGIA | L7: =LOOKUP(Q1,DATOS!A:A,DATOS!O:O) -> 46105
C8: Policlinico o Servicio | G8: Consultorio | L8: Fecha de Solicitud
C10: HEMATOLOGIA | M10: WIDAL
E11: Hematocrito: | G11: =LOOKUP(Q1,DATOS!A:A,DATOS!U:U) -> 54 | H11: % | M11: EBERTH O: | N11: =LOOKUP(Q1,DATOS!A:A,DATOS!CO:CO) -> -
E12: Hemoglobina: | G12: =LOOKUP(Q1,DATOS!A:A,DATOS!V:V) -> 18.1 | H12: g/dL | M12: EBERTH H: | N12: =LOOKUP(Q1,DATOS!A:A,DATOS!CP:CP) -> -
E13: Plaquetas: | G13: =LOOKUP(Q1,DATOS!A:A,DATOS!AJ:AJ) -> 103000 | H13: uL | M13: PARATIPHY A: | N13: =LOOKUP(Q1,DATOS!A:A,DATOS!CQ:CQ) -> -
E14: Globulos Blancos: | F14: =LOOKUP(Q1,DATOS!A:A,DATOS!Z:Z) -> 4660 | H14: uL | M14: PARATIPHY B: | N14: =LOOKUP(Q1,DATOS!A:A,DATOS!CR:CR) -> -
E15: Cayados: | F15: =LOOKUP(Q1,DATOS!A:A,DATOS!AE:AE) -> 0 | H15: %
E16: Segmentados: | F16: =LOOKUP(Q1,DATOS!A:A,DATOS!AA:AA) -> 35 | H16: % | L16: SEDIMENTO URINARIO
E17: Eosinofilos: | F17: =LOOKUP(Q1,DATOS!A:A,DATOS!AD:AD) -> 6 | H17: % | K17: Cel. Epitelia.: | M17: =LOOKUP(Q1,DATOS!A:A,DATOS!DO:DO) -> 0
E18: Basófilos: | F18: =LOOKUP(Q1,DATOS!A:A,DATOS!AH:AH) -> 0 | H18: % | K18: Leucocitos: | M18: =LOOKUP(Q1,DATOS!A:A,DATOS!DM:DM) -> 0
E19: Linfocitos: | F19: =LOOKUP(Q1,DATOS!A:A,DATOS!AB:AB) -> 58 | H19: % | K19: Hematies: | M19: =LOOKUP(Q1,DATOS!A:A,DATOS!DN:DN) -> 0
E20: Monocitos: | F20: =LOOKUP(Q1,DATOS!A:A,DATOS!AC:AC) -> 1 | H20: % | K20: Bacterias: | M20: =LOOKUP(Q1,DATOS!A:A,DATOS!DP:DP) -> 0
E21: Total: | F21: =SUM(F15:G20) -> 100 | K21: Cel. Renales: | M21: =LOOKUP(Q1,DATOS!A:A,DATOS!DQ:DQ) -> 0
K22: Fil. Mucoso: | M22: =LOOKUP(Q1,DATOS!A:A,DATOS!DR:DR) -> 0
K23: Piocitos: | M23: =LOOKUP(Q1,DATOS!A:A,DATOS!DL:DL) -> 0
K24: Cristales: | M24: =LOOKUP(Q1,DATOS!A:A,DATOS!DS:DS) -> 0
K25: Otros: | M25: =LOOKUP(Q1,DATOS!A:A,DATOS!DX:DX) -> 0
B27: Elaborado por: Anahi Vigabriel C. | G27: Fecha de Reporte: | I27: =LOOKUP(Q1,DATOS!A:A,DATOS!P:P) -> 46156 | P27: Hrs: | Q27: =NOW() -> 46197.396

Sheet LIQUIDOS
B1: CAJA NACIONAL DE SALUD - PAISE EL ALTO | J1: 100
B2: CAJA NACIONAL DE SALUD - PAISE EL ALTO
B3: =LOOKUP(J1,DATOS!A:A,DATOS!B:B) -> 100 | C3: SERVICIO DE LABORATORIO CLINICO | H3: A.V.C.: | I3: =LOOKUP(J1,DATOS!A:A,DATOS!J:J) -> 0
C4: RESULTADOS DE LABORATORIO | H4: BENEF: | I4: =LOOKUP(J1,DATOS!A:A,DATOS!K:K) -> 0
B5: NOMBRES Y APELLIDOS: | D5: =LOOKUP(J1,DATOS!A:A,DATOS!G:G) | I5: EDAD: | J5: =LOOKUP(J1,DATOS!A:A,DATOS!H:H) -> 0 | K5: ã
B6: FECHA DE SOLICITUD: | D6: =LOOKUP(J1,DATOS!A:A,DATOS!O:O) -> 0 | H6: GENERO: | I6: =LOOKUP(J1,DATOS!A:A,DATOS!I:I) -> 0
B7: SOLICITADO POR: | C7: =LOOKUP(J1,DATOS!A:A,DATOS!N:N) -> 0 | G7: CONSUL/ESPECIAL.: | I7: =LOOKUP(J1,DATOS!A:A,DATOS!M:M) -> 0
C9: LÍQUIDO | F9: =LOOKUP(J1,DATOS!A:A,DATOS!ED:ED) -> 0
B11: EXAMEN FISICO
C12: VOLUMEN: | F12: =LOOKUP(J1,DATOS!A:A,DATOS!EE:EE) -> 0 | H12: ml
C13: COLOR: | F13: =LOOKUP(J1,DATOS!A:A,DATOS!EF:EF) -> 0
C14: ASPECTO: | F14: =LOOKUP(J1,DATOS!A:A,DATOS!EG:EG) -> 0
C15: PH: | F15: =LOOKUP(J1,DATOS!A:A,DATOS!EH:EH) -> 0
C16: REACCIÓN: | F16: =LOOKUP(J1,DATOS!A:A,DATOS!EI:EI) -> 0
C17: OTROS: | F17: =LOOKUP(J1,DATOS!A:A,DATOS!EJ:EJ) -> 0
C19: LUEGO DE LA CENTRIFUGACION
C20: =LOOKUP(J1,DATOS!A:A,DATOS!EK:EK) -> 0
C21: COLOR: | F21: =LOOKUP(J1,DATOS!A:A,DATOS!EL:EL) -> 0
C22: ASPECTO: | F22: =LOOKUP(J1,DATOS!A:A,DATOS!EM:EM) -> 0
B24: EXAMEN QUIMICO
C25: GLUCOSA: | F25: =LOOKUP(J1,DATOS!A:A,DATOS!EN:EN) -> 0 | H25: mg/dl
C26: PROTEINAS: | F26: =LOOKUP(J1,DATOS!A:A,DATOS!EO:EO) -> 0 | H26: g/dl
E27: Observaciones: | F27: =LOOKUP(J1,DATOS!A:A,DATOS!EP:EP) -> 0
B29: EXAMEN CITOLOGICO MICROSCOPICO
C30: Leucocitos: | F30: =LOOKUP(J1,DATOS!A:A,DATOS!EQ:EQ) -> 0 | H30: cel/mm3
C31: PMN: | F31: =LOOKUP(J1,DATOS!A:A,DATOS!ER:ER) -> 0 | H31: %
C32: MN: | F32: =LOOKUP(J1,DATOS!A:A,DATOS!ES:ES) -> 0 | H32: %
B33: OBSERVACIONES: | F33: =LOOKUP(J1,DATOS!A:A,DATOS!ET:ET) -> 0
B35: EXAMEN SEDIMENTO EN FRESCO
C37: Leucocitos: | F37: =LOOKUP(J1,DATOS!A:A,DATOS!EU:EU) -> 0 | H37: POR CAMPO
C38: Hematíes: | F38: =LOOKUP(J1,DATOS!A:A,DATOS!EV:EV) -> 0 | H38: POR CAMPO
C39: Bacterias: | F39: =LOOKUP(J1,DATOS!A:A,DATOS!EW:EW) -> 0
C40: Observaciones: | F40: =LOOKUP(J1,DATOS!A:A,DATOS!EX:EX) -> 0
F46: FIRMA Y SELLO DEL RESPONSABLE
B47: Fecha de Reporte: | E47: =LOOKUP(J1,DATOS!A:A,DATOS!P:P) -> 0 | I47: Hrs. | J47: =NOW() -> 46197.396

Sheet ESPERMATO
C1: CAJA NACIONAL DE SALUD - PAISE EL ALTO | K1: 12
C2: CAJA NACIONAL DE SALUD - PAISE EL ALTO
C3: =LOOKUP(K1,DATOS!A:A,DATOS!B:B) -> 12 | D3: SERVICIO DE LABORATORIO CLINICO | I3: A.V.C.: | J3: =LOOKUP(K1,DATOS!A:A,DATOS!J:J) -> 890805 CCH
D4: RESULTADOS DE LABORATORIO | I4: BENEF: | J4: =LOOKUP(K1,DATOS!A:A,DATOS!K:K) -> 50
C5: NOMBRES Y APELLIDOS: | E5: =LOOKUP(K1,DATOS!A:A,DATOS!G:G) -> TORREZ VARGAS DELIA | J5: EDAD: | K5: =LOOKUP(K1,DATOS!A:A,DATOS!H:H) -> 35 | L5: ã
C6: FECHA DE SOLICITUD: | E6: =LOOKUP(K1,DATOS!A:A,DATOS!O:O) -> 46141 | I6: GENERO: | J6: =LOOKUP(K1,DATOS!A:A,DATOS!I:I) -> FEMENINO
C7: SOLICITADO POR: | D7: =LOOKUP(K1,DATOS!A:A,DATOS!N:N) -> DRA. CHAMBI | H7: CONSUL/ESPECIAL.: | J7: =LOOKUP(K1,DATOS!A:A,DATOS!M:M) -> GINECOLOGIA
D9: ESPERMATOGRAMA
B11: Fecha y hora de Obtecion de muestra:
B12: Hora de Recepcion en Laboratorio:
B13: Dias de Abstinencia:
B15: EXAMEN MACROSCOPICO
C16: PARAMETRO
C17: VOLUMEN:
C18: COLOR:
C19: Ph:
C20: VISCOSIDAD:
C21: ASPECTO:
C22: LICUEFACCION:
C23: COAGULACION:
C24: OLOR:
G49: FIRMA Y SELLO DEL RESPONSABLE
C50: Fecha de Reporte: | F50: =LOOKUP(K1,DATOS!A:A,DATOS!P:P) -> 46156 | J50: Hrs. | K50: =NOW() -> 46197.396

Sheet VACIO
Q1: 3
P2: =LOOKUP(Q1,DATOS!A:A,DATOS!J:J) -> 800720 GSE
J3: =LOOKUP(Q1,DATOS!A:A,DATOS!B:B) -> 3 | P3: =LOOKUP(Q1,DATOS!A:A,DATOS!K:K) -> 58 | R3: =LOOKUP(Q1,DATOS!A:A,DATOS!H:H) -> 73
C5: =LOOKUP(Q1,DATOS!A:A,DATOS!N:N) -> DR. RADA | H5: PAISE EL ALTO | L5: =LOOKUP(Q1,DATOS!A:A,DATOS!G:G) -> SALLINAS ASQUICHO FELIPA
C8: =LOOKUP(Q1,DATOS!A:A,DATOS!L:L) -> PAISE EL ALTO | G8: =LOOKUP(Q1,DATOS!A:A,DATOS!M:M) -> NEUMOLOGIA | L8: =LOOKUP(Q1,DATOS!A:A,DATOS!O:O) -> 46154
B21: Elaborado por: Anahi Vigabriel C. | I21: =LOOKUP(Q1,DATOS!A:A,DATOS!P:P) -> 46156 | P21: Hrs: | Q21: =NOW() -> 46197.396

Sheet DATOS
D1: DATOS DEL PACIENTE | U1: HEMOGRAMA | AR1: COAGULOGRAMA | BC1: QUMICAS | BY1: ELECTROLITOS | CB1: ORINA DE 24 HRS. | CF1: SEROLOGIA | CO1: WIDAL | CS1: MICROALBUMINURIA | CV1: EGO | DT1: CILINDROS | EA1: MICROALBUMINURIA | ED1: LIQUIDOS | EK1: LUEGO DE LA CENTRIFUGACION | EN1: EXAMEN QUIMICO | EQ1: EXAMEN MICROSCOPICO | ET1: NO PROCEDE A RECUENTO DIFERENCIA | EU1: SEDIMENTO | EY1: TOLERANCIA A LA GLUCOSA
A2: Nº | B2: COD. | C2: EMERG. | D2: PATERNO | E2: MATERNO | F2: NOMBRES | G2: NOMBRE COMPLETO | H2: EDAD | I2: GENERO | J2: MATRICULA | K2: BENEFICIARIO | L2: POLICLINICO | M2: CONSULTORIO | N2: MEDICO SOLICITANTE | O2: FECHA DE SOLICITUD | P2: FECHA DE REPORTE | Q2: TELE/CEL | R2: DIAGN | S2: RESPONSABLE | T2: PENDIENTES/ OBSERVACIONES | U2: HTO | V2: HB | W2: V.C.M. | X2: H.C.M. | Y2: C.H.C.M. | Z2: GLOBULOS BLANCOS | AA2: SEG | AB2: LINF. | AC2: MON. | AD2: EOSI. | AE2: CAY. | AF2: MIELO | AG2: METAMIE | AH2: BASO. | AI2: TOTAL | AJ2: PLAQUETAS | AK2: GRUPO SANGUINEO | AL2: RETICULOCITOS | AM2: VES 1 HORA | AN2: VES 2HORA | AQ2: INDICE DE KATZ | AR2: TIEMPO DE SANGRIA MINUTOS | AS2: TIEMPO DE SANGRIA SEGUNDOS | AT2: T. DE COAGULACION MINUTOS | AU2: T. DE COAGULACION SEGUNDOS | AV2: TIEMPO DE PROTROMBINA | AW2: ACTIVIDAD | AX2: INR | AY2: COMENTARIO SERIE ROJA | AZ2: COMENTARIO SERIE BLANCA | BA2: COMENTARIO PLAQUETAS | BB2: OBSERVACIONES | BC2: GLI | BD2: CREA | BE2: UREA | BF2: NUS | BG2: ACIDO URICO | BH2: HBA 1C | BI2: COL | BJ2: TRI | BK2: HDL | BL2: LDL | BM2: VLDL | BN2: GOT | BO2: GPT | BP2: FAL | BQ2: BD | BR2: BI | BS2: BT | BT2: PROT | BU2: ALB | BV2: GLOBULINAS | BW2: REL ALB/GLO | BX2: AMILASA | BY2: SODIO | BZ2: POTASIO | CA2: CLORO | CB2: PROT 24 HRS. | CC2: CREA EN ORINA | CD2: VOLUMEN | CE2: OBSERVACIONES | CF2: PCR | CG2: FR | CH2: ASTO | CI2: HIV | CJ2: TES. EMBARAZO | CK2: RPR | CL2: PSA PRUEBA RAPIDA | CM2: H. PYLORI EN SUERO | CN2: HEPATITIS B | CO2: O | CP2: H | CQ2: A | CR2: B | CS2: A/C | CT2: ALBUMINA | CU2: CREATININA | CV2: VOLUMEN | CW2: COLOR | CX2: OLOR | CY2: ASPECTO | CZ2: ESPUMA | DA2: OTROS | DB2: SEDIMENTO | DC2: DENSIDAD | DD2: PH | DE2: PROT | DF2: GLUCOSA | DG2: CETONAS | DH2: BILIRRUBINAS | DI2: SANGRE | DJ2: UROBILINOGENO | DK2: NITRITOS | DL2: PIOCITOS | DM2: LEUCOCITOS | DN2: ERITROCITOS | DO2: C. EPITELIALES | DP2: BACTERIAS | DQ2: CEL. RENALES | DR2: FILAMENTO MUCOSO | DS2: CRISTALES | DT2: HIALINOS | DU2: GRANULOSO | DV2: HEMATICO | DW2: CEREO | DX2: OTROS | DY2: OBSERVACIONES1 | DZ2: OBSERVACIONES 2 | EA2: Relación A/C. | EB2: ALBUMINA | EC2: CREATININA | ED2: TIPO DE LIQUIDO | EE2: VOLUMEN | EF2: COLOR | EG2: ASPECTO | EH2: PH | EI2: REACCION | EJ2: OTROS | EK2: OBS. | EL2: COLOR | EM2: ASPECTO | EN2: GLUCOSA | EO2: PROTEINAS | EP2: OBSERVACIONES | EQ2: LEUCOCITOS | ER2: PMN% | ES2: MN% | ET2: OBS. | EU2: LEUCOCITOS | EV2: HEMATIES | EW2: BACTERIAS | EX2: OTROS | EY2: BASAL | EZ2: HORA | FA2: 1HORA | FB2: HORA | FC2: 2 HORA | FD2: HORA
A3: 1 | B3: 1 | D3: SIRPA | E3: SIRPA | F3: ANCELMO | G3: =CONCATENATE(D3," ",E3," ",F3) -> SIRPA SIRPA ANCELMO | H3: 72 | I3: MASCULINO | J3: 530421 SSA | K3: ID | L3: PAISE EL ALTO | M3: CARDIOLOGIA | N3: DR. ZAMBRANA | O3: 46108 | P3: 46156 | U3: 51 | V3: 16.2 | Z3: 6020 | AA3: 69 | AB3: 28 | AC3: 2 | AD3: 1 | AI3: =SUM(AA3:AH3) -> 100 | AJ3: 218000 | AM3: 5 | AO3: =AN3/2 -> 0 | AP3: =AM3+AO3 -> 5 | AQ3: =IF(AN3="","",AP3/2) | AR3: - | AS3: - | AT3: - | AU3: - | AV3: 12 | AW3: 100 | AX3: 1 | BC3: 87 | BD3: 1.4 | BF3: =IF(BE3="","",BE3/2.14) | BI3: 176 | BJ3: 132 | BL3: =IF(BK3="","",IF(AND(BJ3>400,BK3>1),"No Procede",IF(BK3<1,"",BI3-BK3-(BJ3/5)))) | BM3: =IF(BK3="","",IF(AND(BJ3>400,BK3>1),"NO PROCEDE",IF(BK3="","",BJ3/5))) | BT3: 6.7 | BU3: 3.6 | BV3: =IF(OR(BT3="",BU3=""),"",ROUND(BT3-BU3,1)) -> 3.1 | BW3: =IF(OR(BT3="",BU3=""),"",ROUND(BU3/BV3,1)) -> 1.2 | CO3: - | CP3: - | CQ3: - | CR3: -
A4: 2 | B4: 2 | D4: CONDORI | E4: LEOCA | F4: CONZI AMALIA | G4: =CONCATENATE(D4," ",E4," ",F4) -> CONDORI LEOCA CONZI AMALIA | H4: 47 | I4: FEMENINO | J4: 795222 CLC | K4: ID | L4: PAISE EL ALTO | M4: REUMATOLOGIA | N4: DR. CHAVARRIA | O4: 46097 | P4: 46156 | U4: 48 | V4: 15.3 | Z4: 8210 | AA4: 70 | AB4: 27 | AC4: 3 | AI4: =SUM(AA4:AH4) -> 100 | AJ4: 298000 | AM4: 33 | AO4: =AN4/2 -> 0 | AP4: =AM4+AO4 -> 33 | AQ4: =IF(AN4="","",AP4/2) | AR4: - | AS4: - | AT4: - | AU4: - | AV4: - | AW4: - | AX4: - | BC4: 83 | BD4: 1 | BF4: =IF(BE4="","",BE4/2.14) | BL4: =IF(BK4="","",IF(AND(BJ4>400,BK4>1),"No Procede",IF(BK4<1,"",BI4-BK4-(BJ4/5)))) | BM4: =IF(BK4="","",IF(AND(BJ4>400,BK4>1),"NO PROCEDE",IF(BK4="","",BJ4/5))) | BN4: 30 | BO4: 30 | BU4: 3.3 | BV4: =IF(OR(BT4="",BU4=""),"",ROUND(BT4-BU4,1)) | BW4: =IF(OR(BT4="",BU4=""),"",ROUND(BU4/BV4,1)) | CE4: FOSFATA ALCALINA NHR | CF4: 6.4 | CG4: 256 | CO4: - | CP4: - | CQ4: - | CR4: -
A5: 3 | B5: 3 | C5: X | D5: SALLINAS | E5: ASQUICHO | F5: FELIPA | G5: =CONCATENATE(D5," ",E5," ",F5) -> SALLINAS ASQUICHO FELIPA | H5: 73 | I5: FEMENINO | J5: 800720 GSE | K5: 58 | L5: PAISE EL ALTO | M5: NEUMOLOGIA | N5: DR. RADA | O5: 46154 | P5: 46156 | U5: 46 | V5: 14.8 | Z5: 6560 | AA5: 65 | AB5: 33 | AC5: 1 | AD5: 1 | AI5: =SUM(AA5:AH5) -> 100 | AJ5: 323000 | AM5: - | AO5: =AN5/2 -> 0 | AP5: =AM5+AO5 -> #VALUE! | AQ5: =IF(AN5="","",AP5/2) | AR5: - | AS5: - | AT5: - | AU5: - | AV5: - | AW5: - | AX5: - | BC5: 90 | BD5: 1.1 | BF5: =IF(BE5="","",BE5/2.14) | BL5: =IF(BK5="","",IF(AND(BJ5>400,BK5>1),"No Procede",IF(BK5<1,"",BI5-BK5-(BJ5/5)))) | BM5: =IF(BK5="","",IF(AND(BJ5>400,BK5>1),"NO PROCEDE",IF(BK5="","",BJ5/5))) | BN5: 45 | BO5: 31 | BQ5: 0.1 | BR5: 0.1 | BS5: =IF(BQ5="","",SUM(BQ5:BR5)) -> 0.2 | BV5: =IF(OR(BT5="",BU5=""),"",ROUND(BT5-BU5,1)) | BW5: =IF(OR(BT5="",BU5=""),"",ROUND(BU5/BV5,1)) | CF5: <0,8 | CO5: - | CP5: - | CQ5: - | CR5: -
A6: 4 | B6: 4 | D6: CONDORI | E6: PACO | F6: JUAN | G6: =CONCATENATE(D6," ",E6," ",F6) -> CONDORI PACO JUAN | H6: 82 | I6: MASCULINO | J6: 430610 CPJ | K6: ID | L6: PAISE EL ALTO | M6: CARDIOLOGIA | N6: DR. ZAMBRANA | O6: 46111 | P6: 46156 | U6: 62 | V6: 20.8 | Z6: 5890 | AA6: 59 | AB6: 41 | AI6: =SUM(AA6:AH6) -> 100 | AJ6: 169000 | AM6: 0 | AO6: =AN6/2 -> 0 | AP6: =AM6+AO6 -> 0 | AQ6: =IF(AN6="","",AP6/2) | AR6: - | AS6: - | AT6: - | AU6: - | AV6: 13 | AW6: 87 | AX6: 1.09 | BC6: 91 | BD6: 1.4 | BF6: =IF(BE6="","",BE6/2.14) | BI6: 191 | BJ6: 162 | BK6: 49 | BL6: 49 | BM6: =IF(BK6="","",IF(AND(BJ6>400,BK6>1),"NO PROCEDE",IF(BK6="","",BJ6/5))) -> 32.4 | BS6: =IF(BQ6="","",SUM(BQ6:BR6)) | BT6: 7.3 | BU6: 4.2 | BV6: =IF(OR(BT6="",BU6=""),"",ROUND(BT6-BU6,1)) -> 3.1 | BW6: =IF(OR(BT6="",BU6=""),"",ROUND(BU6/BV6,1)) -> 1.4 | CO6: - | CP6: - | CQ6: - | CR6: -
A7: 5 | B7: 5 | D7: COPA | E7: BENIZ | F7: JULIO RAUL | G7: =CONCATENATE(D7," ",E7," ",F7) -> COPA BENIZ JULIO RAUL | H7: 57 | I7: MASCULINO | J7: 680412 CBJ | K7: ID | L7: PAISE EL ALTO | M7: CARDIOLOGIA | N7: DR. ZAMBRANA | O7: 46108 | P7: 46156 | U7: 53 | V7: 17.4 | Z7: 4270 | AA7: 55 | AB7: 41 | AC7: 3 | AD7: 1 | AI7: =SUM(AA7:AH7) -> 100 | AJ7: 198000 | AM7: 9 | AO7: =AN7/2 -> 0 | AP7: =AM7+AO7 -> 9 | AQ7: =IF(AN7="","",AP7/2) | AR7: - | AS7: - | AT7: - | AU7: - | AV7: 13 | AW7: 87 | AX7: 1.09 | BC7: 98 | BD7: 0.8 | BF7: =IF(BE7="","",BE7/2.14) | BI7: 191 | BJ7: 201 | BK7: 39 | BL7: 39 | BM7: =IF(BK7="","",IF(AND(BJ7>400,BK7>1),"NO PROCEDE",IF(BK7="","",BJ7/5))) -> 40.2 | BS7: =IF(BQ7="","",SUM(BQ7:BR7)) | BT7: 7.2 | BU7: 4 | BV7: =IF(OR(BT7="",BU7=""),"",ROUND(BT7-BU7,1)) -> 3.2 | BW7: =IF(OR(BT7="",BU7=""),"",ROUND(BU7/BV7,1)) -> 1.3 | CO7: - | CP7: - | CQ7: - | CR7: -
A8: 6 | B8: 6 | C8: X | D8: MAMANI | E8: CANAVIRI | F8: ROSMERY | G8: =CONCATENATE(D8," ",E8," ",F8) -> MAMANI CANAVIRI ROSMERY | H8: 45 | I8: FEMENINO | J8: 770729 CTF | K8: 50 | L8: PAISE EL ALTO | M8: NEUMOLOGIA | N8: DR. TARIFA | O8: 46154 | P8: 46156 | U8: 52 | V8: 16.5 | Z8: 7160 | AA8: 72 | AB8: 27 | AD8: 1 | AI8: =SUM(AA8:AH8) -> 100 | AJ8: 253000 | AM8: - | AO8: =AN8/2 -> 0 | AP8: =AM8+AO8 -> #VALUE! | AQ8: =IF(AN8="","",AP8/2) | AR8: - | AS8: - | AT8: - | AU8: - | AV8: - | AW8: - | AX8: - | BC8: 96 | BD8: 1.2 | BF8: =IF(BE8="","",BE8/2.14) | BG8: 6.4 | BI8: 169 | BJ8: 107 | BK8: 33 | BL8: 33 | BM8: =IF(BK8="","",IF(AND(BJ8>400,BK8>1),"NO PROCEDE",IF(BK8="","",BJ8/5))) -> 21.4 | BN8: 24 | BO8: 17 | BQ8: 0.3 | BR8: 3.8 | BS8: =IF(BQ8="","",SUM(BQ8:BR8)) -> 4.1 | BT8: 6.4 | BU8: 3.8 | BV8: =IF(OR(BT8="",BU8=""),"",ROUND(BT8-BU8,1)) -> 2.6 | BW8: =IF(OR(BT8="",BU8=""),"",ROUND(BU8/BV8,1)) -> 1.5 | BY8: 143.7 | BZ8: 3.53 | CA8: 113 | CF8: <0,8 | CI8: NO REACTIVO | CO8: - | CP8: - | CQ8: - | CR8: -
A9: 7 | B9: 7 | D9: ACERO | E9: ESPINAL | F9: MARIA ELENA | G9: =CONCATENATE(D9," ",E9," ",F9) -> ACERO ESPINAL MARIA ELENA | H9: 57 | I9: FEMENINO | J9: 685606 AEM | K9: ID | L9: CIMFA EL ALTO | M9: C-18 | N9: DRA. CASTILLO | O9: 46106 | P9: 46156 | AI9: =SUM(AA9:AH9) -> 0 | AM9: - | AO9: =AN9/2 -> 0 | AP9: =AM9+AO9 -> #VALUE! | AQ9: =IF(AN9="","",AP9/2) | AR9: - | AS9: - | AT9: - | AU9: - | AV9: - | AW9: - | AX9: - | BC9: 96 | BD9: 1.1 | BF9: =IF(BE9="","",BE9/2.14) | BG9: 3.2 | BI9: 286 | BJ9: 275 | BK9: 31 | BL9: 31 | BM9: =IF(BK9="","",IF(AND(BJ9>400,BK9>1),"NO PROCEDE",IF(BK9="","",BJ9/5))) -> 55 | BS9: =IF(BQ9="","",SUM(BQ9:BR9)) | BV9: =IF(OR(BT9="",BU9=""),"",ROUND(BT9-BU9,1)) | BW9: =IF(OR(BT9="",BU9=""),"",ROUND(BU9/BV9,1)) | CO9: - | CP9: - | CQ9: - | CR9: -
A10: 8 | B10: 8 | D10: CHOQUE | E10: VILLCA | F10: AMALIA | G10: =CONCATENATE(D10," ",E10," ",F10) -> CHOQUE VILLCA AMALIA | H10: 67 | I10: FEMENINO | J10: 571031 RCQ | K10: 50 | L10: CIMFA EL ALTO | M10: C-12 | N10: DR. MARQUEZ | O10: 46150 | P10: 46156 | U10: 58 | V10: 19 | Z10: 9290 | AA10: 70 | AB10: 30 | AI10: =SUM(AA10:AH10) -> 100 | AJ10: 170000 | AM10: 5 | AO10: =AN10/2 -> 0 | AP10: =AM10+AO10 -> 5 | AQ10: =IF(AN10="","",AP10/2) | AR10: - | AS10: - | AT10: - | AU10: - | AV10: - | AW10: - | AX10: - | BC10: 117 | BD10: 1 | BF10: =IF(BE10="","",BE10/2.14) | BG10: 3 | BI10: 175 | BJ10: 113 | BK10: 48 | BL10: 48 | BM10: =IF(BK10="","",IF(AND(BJ10>400,BK10>1),"NO PROCEDE",IF(BK10="","",BJ10/5))) -> 22.6 | BS10: =IF(BQ10="","",SUM(BQ10:BR10)) | BV10: =IF(OR(BT10="",BU10=""),"",ROUND(BT10-BU10,1)) | BW10: =IF(OR(BT10="",BU10=""),"",ROUND(BU10/BV10,1)) | CF10: <0,8 | CG10: <8 | CH10: <200 | CO10: - | CP10: - | CQ10: - | CR10: -
A11: 9 | B11: 9 | D11: PAREDES | E11: CHOQUE | F11: POLICARPIO | G11: =CONCATENATE(D11," ",E11," ",F11) -> PAREDES CHOQUE POLICARPIO | H11: 59 | I11: MASCULINO | J11: 661207 PCP | K11: ID | L11: PAISE EL ALTO | M11: CARDIOLOGIA | N11: DR. ZAMBRANA | O11: 46104 | P11: 46156 | U11: 52 | V11: 17.2 | Z11: 4870 | AA11: 59 | AB11: 39 | AD11: 2 | AI11: =SUM(AA11:AH11) -> 100 | AJ11: 211000 | AM11: 4 | AO11: =AN11/2 -> 0 | AP11: =AM11+AO11 -> 4 | AQ11: =IF(AN11="","",AP11/2) | AR11: - | AS11: - | AT11: - | AU11: - | AV11: 12 | AW11: 100 | AX11: 1 | BC11: 84 | BD11: 1.3 | BF11: =IF(BE11="","",BE11/2.14) | BI11: 180 | BJ11: 136 | BK11: 65 | BL11: 65 | BM11: =IF(BK11="","",IF(AND(BJ11>400,BK11>1),"NO PROCEDE",IF(BK11="","",BJ11/5))) -> 27.2 | BS11: =IF(BQ11="","",SUM(BQ11:BR11)) | BT11: 6.8 | BU11: 3.9 | BV11: =IF(OR(BT11="",BU11=""),"",ROUND(BT11-BU11,1)) -> 2.9 | BW11: =IF(OR(BT11="",BU11=""),"",ROUND(BU11/BV11,1)) -> 1.3 | CO11: - | CP11: - | CQ11: - | CR11: -
A12: 10 | B12: 10 | D12: CONTRERAS | E12: ALI | F12: OVIDIO | G12: =CONCATENATE(D12," ",E12," ",F12) -> CONTRERAS ALI OVIDIO | H12: 41 | I12: MASCULINO | J12: 850501 CAO | K12: ID | L12: PAISE EL ALTO | M12: C-45 | N12: DR. AGUAYO | O12: 46155 | P12: 46156 | U12: 64 | V12: 21 | AI12: =SUM(AA12:AH12) -> 0 | AM12: - | AO12: =AN12/2 -> 0 | AP12: =AM12+AO12 -> #VALUE! | AQ12: =IF(AN12="","",AP12/2) | AR12: - | AS12: - | AT12: - | AU12: - | AV12: - | AW12: - | AX12: - | BF12: =IF(BE12="","",BE12/2.14) | BI12: 207 | BJ12: 158 | BL12: =IF(BK12="","",IF(AND(BJ12>400,BK12>1),"No Procede",IF(BK12<1,"",BI12-BK12-(BJ12/5)))) | BM12: =IF(BK12="","",IF(AND(BJ12>400,BK12>1),"NO PROCEDE",IF(BK12="","",BJ12/5))) | BS12: =IF(BQ12="","",SUM(BQ12:BR12)) | BV12: =IF(OR(BT12="",BU12=""),"",ROUND(BT12-BU12,1)) | BW12: =IF(OR(BT12="",BU12=""),"",ROUND(BU12/BV12,1)) | CO12: - | CP12: - | CQ12: - | CR12: -
A13: 11 | B13: 11 | D13: CHURA | E13: HUACOTO | F13: ANGELINO | G13: =CONCATENATE(D13," ",E13," ",F13) -> CHURA HUACOTO ANGELINO | H13: 68 | I13: MASCULINO | J13: 570805 CHA | K13: ID | L13: PAISE EL ALTO | M13: CARDIOLOGIA | N13: DR. ZAMBRANA | O13: 46105 | P13: 46156 | U13: 54 | V13: 18.1 | Z13: 4660 | AA13: 35 | AB13: 58 | AC13: 1 | AD13: 6 | AI13: =SUM(AA13:AH13) -> 100 | AJ13: 103000 | AM13: 41 | AO13: =AN13/2 -> 0 | AP13: =AM13+AO13 -> 41 | AQ13: =IF(AN13="","",AP13/2) | AR13: - | AS13: - | AT13: - | AU13: - | AV13: 14 | AW13: 77 | AX13: 1.18 | BC13: 81 | BD13: 1.2 | BF13: =IF(BE13="","",BE13/2.14) | BI13: 149 | BJ13: 111 | BL13: =IF(BK13="","",IF(AND(BJ13>400,BK13>1),"No Procede",IF(BK13<1,"",BI13-BK13-(BJ13/5)))) | BM13: =IF(BK13="","",IF(AND(BJ13>400,BK13>1),"NO PROCEDE",IF(BK13="","",BJ13/5))) | BQ13: 0.3 | BR13: 1.7 | BS13: =IF(BQ13="","",SUM(BQ13:BR13)) -> 2 | BU13: 3.7 | BV13: =IF(OR(BT13="",BU13=""),"",ROUND(BT13-BU13,1)) | BW13: =IF(OR(BT13="",BU13=""),"",ROUND(BU13/BV13,1)) | CE13: FOSFATA ALCALINA NHR | CO13: - | CP13: - | CQ13: - | CR13: -
A14: 12 | B14: 12 | D14: TORREZ | E14: VARGAS | F14: DELIA | G14: =CONCATENATE(D14," ",E14," ",F14) -> TORREZ VARGAS DELIA | H14: 35 | I14: FEMENINO | J14: 890805 CCH | K14: 50 | L14: PAISE EL ALTO | M14: GINECOLOGIA | N14: DRA. CHAMBI | O14: 46141 | P14: 46156 | U14: 46 | V14: 14.7 | Z14: 8430 | AA14: 78 | AB14: 19 | AC14: 1 | AD14: 2 | AI14: =SUM(AA14:AH14) -> 100 | AJ14: 215000 | AM14: 63 | AO14: =AN14/2 -> 0 | AP14: =AM14+AO14 -> 63 | AQ14: =IF(AN14="","",AP14/2) | AR14: - | AS14: - | AT14: - | AU14: - | AV14: 12 | AW14: 100 | AX14: 1 | BC14: 83 | BF14: =IF(BE14="","",BE14/2.14) | BL14: =IF(BK14="","",IF(AND(BJ14>400,BK14>1),"No Procede",IF(BK14<1,"",BI14-BK14-(BJ14/5)))) | BM14: =IF(BK14="","",IF(AND(BJ14>400,BK14>1),"NO PROCEDE",IF(BK14="","",BJ14/5))) | BN14: 18 | BO14: 13 | BQ14: 0.3 | BR14: 0.6 | BS14: =IF(BQ14="","",SUM(BQ14:BR14)) -> 0.9 | BT14: 6.9 | BU14: 6.2 | BV14: =IF(OR(BT14="",BU14=""),"",ROUND(BT14-BU14,1)) -> 0.7 | BW14: =IF(OR(BT14="",BU14=""),"",ROUND(BU14/BV14,1)) -> 8.9 | CF14: 1.6 | CO14: - | CP14: - | CQ14: - | CR14: - | CV14: 80 | CW14: Amarillo | CX14: Sui Generis | CY14: Lig. Opalescente | CZ14: Fugaz | DC14: 1020 | DD14: 6.5 | DE14: No Cont. | DF14: No Cont. | DG14: No Cont. | DH14: No Cont. | DI14: No Cont. | DJ14: Normal | DK14: Negativo | DM14: 8-7XC | DO14: 7-15XC | DP14: AUMENTADAS | DQ14: 0-1XC
A15: 13 | B15: 13 | C15: X | D15: ROJAS | E15: ALANOCA | F15: RAQUEL | G15: =CONCATENATE(D15," ",E15," ",F15) -> ROJAS ALANOCA RAQUEL | H15: 45 | I15: FEMENINO | J15: 805910 RAR | K15: ID | L15: PAISE EL ALTO | M15: REUMATOLOGIA | N15: DR. CHAVARRIA | O15: 46108 | P15: 46156 | U15: 60 | V15: 19.8 | Z15: 7100 | AA15: 70 | AB15: 30 | AI15: =SUM(AA15:AH15) -> 100 | AJ15: 259000 | AM15: - | AO15: =AN15/2 -> 0 | AP15: =AM15+AO15 -> #VALUE! | AQ15: =IF(AN15="","",AP15/2) | AR15: - | AS15: - | AT15: - | AU15: - | AV15: - | AW15: - | AX15: - | BC15: 88 | BD15: 0.9 | BF15: =IF(BE15="","",BE15/2.14) | BL15: =IF(BK15="","",IF(AND(BJ15>400,BK15>1),"No Procede",IF(BK15<1,"",BI15-BK15-(BJ15/5)))) | BM15: =IF(BK15="","",IF(AND(BJ15>400,BK15>1),"NO PROCEDE",IF(BK15="","",BJ15/5))) | BN15: 35 | BO15: 35 | BS15: =IF(BQ15="","",SUM(BQ15:BR15)) | BU15: 3.4 | BV15: =IF(OR(BT15="",BU15=""),"",ROUND(BT15-BU15,1)) | BW15: =IF(OR(BT15="",BU15=""),"",ROUND(BU15/BV15,1)) | CE15: FOSFATA ALCALINA NHR | CF15: 1.6 | CO15: - | CP15: - | CQ15: - | CR15: -
A16: 14 | B16: 14 | C16: X | D16: VARGAS | E16: ARUQUIPA | F16: MILLER | G16: =CONCATENATE(D16," ",E16," ",F16) -> VARGAS ARUQUIPA MILLER | H16: 43 | I16: MASCULINO | J16: 820716 VAM | K16: ID | L16: OTROS | M16: CIS ACHACACHI | N16: DR. CHAPARRO | O16: 46142 | P16: 46156 | U16: 57 | V16: 18.8 | Z16: 5080 | AA16: 61 | AB16: 39 | AI16: =SUM(AA16:AH16) -> 100 | AM16: - | AO16: =AN16/2 -> 0 | AP16: =AM16+AO16 -> #VALUE! | AQ16: =IF(AN16="","",AP16/2) | AR16: - | AS16: - | AT16: - | AU16: - | AV16: - | AW16: - | AX16: - | BC16: 86 | BD16: 1.2 | BF16: =IF(BE16="","",BE16/2.14) | BI16: 186 | BJ16: 205 | BL16: =IF(BK16="","",IF(AND(BJ16>400,BK16>1),"No Procede",IF(BK16<1,"",BI16-BK16-(BJ16/5)))) | BM16: =IF(BK16="","",IF(AND(BJ16>400,BK16>1),"NO PROCEDE",IF(BK16="","",BJ16/5))) | BN16: 36 | BO16: 35 | BS16: =IF(BQ16="","",SUM(BQ16:BR16)) | BV16: =IF(OR(BT16="",BU16=""),"",ROUND(BT16-BU16,1)) | BW16: =IF(OR(BT16="",BU16=""),"",ROUND(BU16/BV16,1)) | CF16: <0,8 | CG16: <8 | CO16: - | CP16: - | CQ16: - | CR16: - | CV16: 70 | CW16: Amarillo | CX16: Sui Generis | CY16: Limpido | CZ16: Fugaz | DC16: 1020 | DD16: 6.5 | DE16: No Cont. | DF16: No Cont. | DG16: No Cont. | DH16: No Cont. | DI16: No Cont. | DJ16: Normal | DK16: Negativo | DM16: 0-1XC | DO16: 0-1XC | DP16: ESCASAS
A17: 15 | B17: 15 | D17: YUJRA | E17: CACHI | F17: ALEJANDRO | G17: =CONCATENATE(D17," ",E17," ",F17) -> YUJRA CACHI ALEJANDRO | H17: 45 | I17: MASCULINO | J17: 810101 YCA | K17: ID | L17: PAISE EL ALTO | M17: REUMATOLOGIA | N17: DR. CHAVARRIA | O17: 46105 | P17: 46156 | U17: 56 | V17: 18.3 | AA17: 61 | AB17: 36 | AC17: 1 | AD17: 2 | AI17: =SUM(AA17:AH17) -> 100 | AJ17: 271000 | AM17: 1 | AO17: =AN17/2 -> 0 | AP17: =AM17+AO17 -> 1 | AQ17: =IF(AN17="","",AP17/2) | AR17: - | AS17: - | AT17: - | AU17: - | AV17: - | AW17: - | AX17: - | BC17: 94 | BD17: 1.4 | BF17: =IF(BE17="","",BE17/2.14) | BG17: 5.1 | BL17: =IF(BK17="","",IF(AND(BJ17>400,BK17>1),"No Procede",IF(BK17<1,"",BI17-BK17-(BJ17/5)))) | BM17: =IF(BK17="","",IF(AND(BJ17>400,BK17>1),"NO PROCEDE",IF(BK17="","",BJ17/5))) | BN17: 31 | BO17: 43 | BS17: =IF(BQ17="","",SUM(BQ17:BR17)) | BU17: 4.2 | BV17: =IF(OR(BT17="",BU17=""),"",ROUND(BT17-BU17,1)) | BW17: =IF(OR(BT17="",BU17=""),"",ROUND(BU17/BV17,1)) | CE17: FOSFATA ALCALINA NHR | CO17: - | CP17: - | CQ17: - | CR17: -
A18: 16 | B18: 16 | C18: X | D18: CONDORI | E18: MOYA | F18: ALEIDA | G18: =CONCATENATE(D18," ",E18," ",F18) -> CONDORI MOYA ALEIDA | H18: 36 | I18: FEMENINO | J18: 810824 CGE | K18: 50 | L18: PAISE EL ALTO | M18: GINECOLOGIA | N18: DR. PRIETO | O18: 46139 | P18: 46156 | AI18: =SUM(AA18:AH18) -> 0 | AM18: - | AO18: =AN18/2 -> 0 | AP18: =AM18+AO18 -> #VALUE! | AQ18: =IF(AN18="","",AP18/2) | AR18: - | AS18: - | AT18: - | AU18: - | AV18: - | AW18: - | AX18: - | BF18: =IF(BE18="","",BE18/2.14) | BL18: =IF(BK18="","",IF(AND(BJ18>400,BK18>1),"No Procede",IF(BK18<1,"",BI18-BK18-(BJ18/5)))) | BM18: =IF(BK18="","",IF(AND(BJ18>400,BK18>1),"NO PROCEDE",IF(BK18="","",BJ18/5))) | BS18: =IF(BQ18="","",SUM(BQ18:BR18)) | BV18: =IF(OR(BT18="",BU18=""),"",ROUND(BT18-BU18,1)) | BW18: =IF(OR(BT18="",BU18=""),"",ROUND(BU18/BV18,1)) | CO18: - | CP18: - | CQ18: - | CR18: - | CV18: 60 | CW18: Amarillo | CX18: Sui Generis | CY18: Limpido | CZ18: Fugaz | DC18: 1015 | DD18: 6.5 | DE18: No Cont. | DF18: No Cont. | DG18: No Cont. | DH18: No Cont. | DI18: No Cont. | DJ18: Normal | DK18: Negativo | DM18: 0-2XC | DO18: 0-1XC | DP18: REGULARES
A19: 17 | B19: 17 | G19: =CONCATENATE(D19," ",E19," ",F19) | P19: 46156 | AI19: =SUM(AA19:AH19) -> 0 | AM19: - | AO19: =AN19/2 -> 0 | AP19: =AM19+AO19 -> #VALUE! | AQ19: =IF(AN19="","",AP19/2) | AR19: - | AS19: - | AT19: - | AU19: - | AV19: - | AW19: - | AX19: - | BF19: =IF(BE19="","",BE19/2.14) | BL19: =IF(BK19="","",IF(AND(BJ19>400,BK19>1),"No Procede",IF(BK19<1,"",BI19-BK19-(BJ19/5)))) | BM19: =IF(BK19="","",IF(AND(BJ19>400,BK19>1),"NO PROCEDE",IF(BK19="","",BJ19/5))) | BS19: =IF(BQ19="","",SUM(BQ19:BR19)) | BV19: =IF(OR(BT19="",BU19=""),"",ROUND(BT19-BU19,1)) | BW19: =IF(OR(BT19="",BU19=""),"",ROUND(BU19/BV19,1)) | CO19: - | CP19: - | CQ19: - | CR19: -
A20: 18 | B20: 18 | G20: =CONCATENATE(D20," ",E20," ",F20) | P20: 46156 | AI20: =SUM(AA20:AH20) -> 0 | AM20: - | AO20: =AN20/2 -> 0 | AP20: =AM20+AO20 -> #VALUE! | AQ20: =IF(AN20="","",AP20/2) | AR20: - | AS20: - | AT20: - | AU20: - | AV20: - | AW20: - | AX20: - | BF20: =IF(BE20="","",BE20/2.14) | BL20: =IF(BK20="","",IF(AND(BJ20>400,BK20>1),"No Procede",IF(BK20<1,"",BI20-BK20-(BJ20/5)))) | BM20: =IF(BK20="","",IF(AND(BJ20>400,BK20>1),"NO PROCEDE",IF(BK20="","",BJ20/5))) | BS20: =IF(BQ20="","",SUM(BQ20:BR20)) | BV20: =IF(OR(BT20="",BU20=""),"",ROUND(BT20-BU20,1)) | BW20: =IF(OR(BT20="",BU20=""),"",ROUND(BU20/BV20,1)) | CO20: - | CP20: - | CQ20: - | CR20: -
A21: 19 | B21: 19 | G21: =CONCATENATE(D21," ",E21," ",F21) | P21: 46156 | AI21: =SUM(AA21:AH21) -> 0 | AM21: - | AO21: =AN21/2 -> 0 | AP21: =AM21+AO21 -> #VALUE! | AQ21: =IF(AN21="","",AP21/2) | AR21: - | AS21: - | AT21: - | AU21: - | AV21: - | AW21: - | AX21: - | BF21: =IF(BE21="","",BE21/2.14) | BL21: =IF(BK21="","",IF(AND(BJ21>400,BK21>1),"No Procede",IF(BK21<1,"",BI21-BK21-(BJ21/5)))) | BM21: =IF(BK21="","",IF(AND(BJ21>400,BK21>1),"NO PROCEDE",IF(BK21="","",BJ21/5))) | BS21: =IF(BQ21="","",SUM(BQ21:BR21)) | BV21: =IF(OR(BT21="",BU21=""),"",ROUND(BT21-BU21,1)) | BW21: =IF(OR(BT21="",BU21=""),"",ROUND(BU21/BV21,1)) | CO21: - | CP21: - | CQ21: - | CR21: -
A22: 20 | B22: 20 | G22: =CONCATENATE(D22," ",E22," ",F22) | P22: 46156 | AI22: =SUM(AA22:AH22) -> 0 | AM22: - | AO22: =AN22/2 -> 0 | AP22: =AM22+AO22 -> #VALUE! | AQ22: =IF(AN22="","",AP22/2) | AR22: - | AS22: - | AT22: - | AU22: - | AV22: - | AW22: - | AX22: - | BF22: =IF(BE22="","",BE22/2.14) | BL22: =IF(BK22="","",IF(AND(BJ22>400,BK22>1),"No Procede",IF(BK22<1,"",BI22-BK22-(BJ22/5)))) | BM22: =IF(BK22="","",IF(AND(BJ22>400,BK22>1),"NO PROCEDE",IF(BK22="","",BJ22/5))) | BS22: =IF(BQ22="","",SUM(BQ22:BR22)) | BV22: =IF(OR(BT22="",BU22=""),"",ROUND(BT22-BU22,1)) | BW22: =IF(OR(BT22="",BU22=""),"",ROUND(BU22/BV22,1)) | CO22: - | CP22: - | CQ22: - | CR22: -
A23: 21 | B23: 21 | G23: =CONCATENATE(D23," ",E23," ",F23) | P23: 46156 | AI23: =SUM(AA23:AH23) -> 0 | AM23: - | AO23: =AN23/2 -> 0 | AP23: =AM23+AO23 -> #VALUE! | AQ23: =IF(AN23="","",AP23/2) | AR23: - | AS23: - | AT23: - | AU23: - | AV23: - | AW23: - | AX23: - | BF23: =IF(BE23="","",BE23/2.14) | BL23: =IF(BK23="","",IF(AND(BJ23>400,BK23>1),"No Procede",IF(BK23<1,"",BI23-BK23-(BJ23/5)))) | BM23: =IF(BK23="","",IF(AND(BJ23>400,BK23>1),"NO PROCEDE",IF(BK23="","",BJ23/5))) | BS23: =IF(BQ23="","",SUM(BQ23:BR23)) | BV23: =IF(OR(BT23="",BU23=""),"",ROUND(BT23-BU23,1)) | BW23: =IF(OR(BT23="",BU23=""),"",ROUND(BU23/BV23,1)) | CO23: - | CP23: - | CQ23: - | CR23: -
A24: 22 | B24: 22 | G24: =CONCATENATE(D24," ",E24," ",F24) | P24: 46156 | AI24: =SUM(AA24:AH24) -> 0 | AM24: - | AO24: =AN24/2 -> 0 | AP24: =AM24+AO24 -> #VALUE! | AQ24: =IF(AN24="","",AP24/2) | AR24: - | AS24: - | AT24: - | AU24: - | AV24: - | AW24: - | AX24: - | BF24: =IF(BE24="","",BE24/2.14) | BL24: =IF(BK24="","",IF(AND(BJ24>400,BK24>1),"No Procede",IF(BK24<1,"",BI24-BK24-(BJ24/5)))) | BM24: =IF(BK24="","",IF(AND(BJ24>400,BK24>1),"NO PROCEDE",IF(BK24="","",BJ24/5))) | BS24: =IF(BQ24="","",SUM(BQ24:BR24)) | BV24: =IF(OR(BT24="",BU24=""),"",ROUND(BT24-BU24,1)) | BW24: =IF(OR(BT24="",BU24=""),"",ROUND(BU24/BV24,1)) | CO24: - | CP24: - | CQ24: - | CR24: -
A25: 23 | B25: 23 | G25: =CONCATENATE(D25," ",E25," ",F25) | P25: 46156 | AI25: =SUM(AA25:AH25) -> 0 | AM25: - | AO25: =AN25/2 -> 0 | AP25: =AM25+AO25 -> #VALUE! | AQ25: =IF(AN25="","",AP25/2) | AR25: - | AS25: - | AT25: - | AU25: - | AV25: - | AW25: - | AX25: - | BF25: =IF(BE25="","",BE25/2.14) | BL25: =IF(BK25="","",IF(AND(BJ25>400,BK25>1),"No Procede",IF(BK25<1,"",BI25-BK25-(BJ25/5)))) | BM25: =IF(BK25="","",IF(AND(BJ25>400,BK25>1),"NO PROCEDE",IF(BK25="","",BJ25/5))) | BS25: =IF(BQ25="","",SUM(BQ25:BR25)) | BV25: =IF(OR(BT25="",BU25=""),"",ROUND(BT25-BU25,1)) | BW25: =IF(OR(BT25="",BU25=""),"",ROUND(BU25/BV25,1)) | CO25: - | CP25: - | CQ25: - | CR25: -
A26: 24 | B26: 24 | G26: =CONCATENATE(D26," ",E26," ",F26) | P26: 46156 | AI26: =SUM(AA26:AH26) -> 0 | AM26: - | AO26: =AN26/2 -> 0 | AP26: =AM26+AO26 -> #VALUE! | AQ26: =IF(AN26="","",AP26/2) | AR26: - | AS26: - | AT26: - | AU26: - | AV26: - | AW26: - | AX26: - | BF26: =IF(BE26="","",BE26/2.14) | BL26: =IF(BK26="","",IF(AND(BJ26>400,BK26>1),"No Procede",IF(BK26<1,"",BI26-BK26-(BJ26/5)))) | BM26: =IF(BK26="","",IF(AND(BJ26>400,BK26>1),"NO PROCEDE",IF(BK26="","",BJ26/5))) | BS26: =IF(BQ26="","",SUM(BQ26:BR26)) | BV26: =IF(OR(BT26="",BU26=""),"",ROUND(BT26-BU26,1)) | BW26: =IF(OR(BT26="",BU26=""),"",ROUND(BU26/BV26,1)) | CO26: - | CP26: - | CQ26: - | CR26: -
A27: 25 | B27: 25 | G27: =CONCATENATE(D27," ",E27," ",F27) | P27: 46156 | AI27: =SUM(AA27:AH27) -> 0 | AM27: - | AO27: =AN27/2 -> 0 | AP27: =AM27+AO27 -> #VALUE! | AQ27: =IF(AN27="","",AP27/2) | AR27: - | AS27: - | AT27: - | AU27: - | AV27: - | AW27: - | AX27: - | BF27: =IF(BE27="","",BE27/2.14) | BL27: =IF(BK27="","",IF(AND(BJ27>400,BK27>1),"No Procede",IF(BK27<1,"",BI27-BK27-(BJ27/5)))) | BM27: =IF(BK27="","",IF(AND(BJ27>400,BK27>1),"NO PROCEDE",IF(BK27="","",BJ27/5))) | BS27: =IF(BQ27="","",SUM(BQ27:BR27)) | BV27: =IF(OR(BT27="",BU27=""),"",ROUND(BT27-BU27,1)) | BW27: =IF(OR(BT27="",BU27=""),"",ROUND(BU27/BV27,1)) | CO27: - | CP27: - | CQ27: - | CR27: -
A28: 26 | B28: 26 | G28: =CONCATENATE(D28," ",E28," ",F28) | I28: MASCULINO | P28: 46156 | AI28: =SUM(AA28:AH28) -> 0 | AM28: - | AO28: =AN28/2 -> 0 | AP28: =AM28+AO28 -> #VALUE! | AQ28: =IF(AN28="","",AP28/2) | AR28: - | AS28: - | AT28: - | AU28: - | AV28: - | AW28: - | AX28: - | BF28: =IF(BE28="","",BE28/2.14) | BL28: =IF(BK28="","",IF(AND(BJ28>400,BK28>1),"No Procede",IF(BK28<1,"",BI28-BK28-(BJ28/5)))) | BM28: =IF(BK28="","",IF(AND(BJ28>400,BK28>1),"NO PROCEDE",IF(BK28="","",BJ28/5))) | BS28: =IF(BQ28="","",SUM(BQ28:BR28)) | BV28: =IF(OR(BT28="",BU28=""),"",ROUND(BT28-BU28,1)) | BW28: =IF(OR(BT28="",BU28=""),"",ROUND(BU28/BV28,1)) | CO28: - | CP28: - | CQ28: - | CR28: -
A29: 27 | B29: 27 | G29: =CONCATENATE(D29," ",E29," ",F29) | L29: CIMFA EL ALTO | P29: 46156 | AI29: =SUM(AA29:AH29) -> 0 | AM29: - | AO29: =AN29/2 -> 0 | AP29: =AM29+AO29 -> #VALUE! | AQ29: =IF(AN29="","",AP29/2) | AR29: - | AS29: - | AT29: - | AU29: - | AV29: - | AW29: - | AX29: - | BF29: =IF(BE29="","",BE29/2.14) | BL29: =IF(BK29="","",IF(AND(BJ29>400,BK29>1),"No Procede",IF(BK29<1,"",BI29-BK29-(BJ29/5)))) | BM29: =IF(BK29="","",IF(AND(BJ29>400,BK29>1),"NO PROCEDE",IF(BK29="","",BJ29/5))) | BS29: =IF(BQ29="","",SUM(BQ29:BR29)) | BV29: =IF(OR(BT29="",BU29=""),"",ROUND(BT29-BU29,1)) | BW29: =IF(OR(BT29="",BU29=""),"",ROUND(BU29/BV29,1)) | CO29: - | CP29: - | CQ29: - | CR29: -
A30: 28 | B30: 28 | G30: =CONCATENATE(D30," ",E30," ",F30) | P30: 46156 | AI30: =SUM(AA30:AH30) -> 0 | AM30: - | AO30: =AN30/2 -> 0 | AP30: =AM30+AO30 -> #VALUE! | AQ30: =IF(AN30="","",AP30/2) | AR30: - | AS30: - | AT30: - | AU30: - | AV30: - | AW30: - | AX30: - | BF30: =IF(BE30="","",BE30/2.14) | BL30: =IF(BK30="","",IF(AND(BJ30>400,BK30>1),"No Procede",IF(BK30<1,"",BI30-BK30-(BJ30/5)))) | BM30: =IF(BK30="","",IF(AND(BJ30>400,BK30>1),"NO PROCEDE",IF(BK30="","",BJ30/5))) | BS30: =IF(BQ30="","",SUM(BQ30:BR30)) | BV30: =IF(OR(BT30="",BU30=""),"",ROUND(BT30-BU30,1)) | BW30: =IF(OR(BT30="",BU30=""),"",ROUND(BU30/BV30,1)) | CO30: - | CP30: - | CQ30: - | CR30: -
A31: 29 | B31: 29 | G31: =CONCATENATE(D31," ",E31," ",F31) | P31: 46156 | AI31: =SUM(AA31:AH31) -> 0 | AM31: - | AO31: =AN31/2 -> 0 | AP31: =AM31+AO31 -> #VALUE! | AQ31: =IF(AN31="","",AP31/2) | AR31: - | AS31: - | AT31: - | AU31: - | AV31: - | AW31: - | AX31: - | BF31: =IF(BE31="","",BE31/2.14) | BL31: =IF(BK31="","",IF(AND(BJ31>400,BK31>1),"No Procede",IF(BK31<1,"",BI31-BK31-(BJ31/5)))) | BM31: =IF(BK31="","",IF(AND(BJ31>400,BK31>1),"NO PROCEDE",IF(BK31="","",BJ31/5))) | BS31: =IF(BQ31="","",SUM(BQ31:BR31)) | BV31: =IF(OR(BT31="",BU31=""),"",ROUND(BT31-BU31,1)) | BW31: =IF(OR(BT31="",BU31=""),"",ROUND(BU31/BV31,1)) | CO31: - | CP31: - | CQ31: - | CR31: -
A32: 30 | B32: 30 | G32: =CONCATENATE(D32," ",E32," ",F32) | P32: 46156 | AI32: =SUM(AA32:AH32) -> 0 | AM32: - | AO32: =AN32/2 -> 0 | AP32: =AM32+AO32 -> #VALUE! | AQ32: =IF(AN32="","",AP32/2) | AR32: - | AS32: - | AT32: - | AU32: - | AV32: - | AW32: - | AX32: - | BF32: =IF(BE32="","",BE32/2.14) | BL32: =IF(BK32="","",IF(AND(BJ32>400,BK32>1),"No Procede",IF(BK32<1,"",BI32-BK32-(BJ32/5)))) | BM32: =IF(BK32="","",IF(AND(BJ32>400,BK32>1),"NO PROCEDE",IF(BK32="","",BJ32/5))) | BS32: =IF(BQ32="","",SUM(BQ32:BR32)) | BV32: =IF(OR(BT32="",BU32=""),"",ROUND(BT32-BU32,1)) | BW32: =IF(OR(BT32="",BU32=""),"",ROUND(BU32/BV32,1)) | CO32: - | CP32: - | CQ32: - | CR32: -
A33: 31 | B33: 31 | G33: =CONCATENATE(D33," ",E33," ",F33) | P33: 46156 | AI33: =SUM(AA33:AH33) -> 0 | AM33: - | AO33: =AN33/2 -> 0 | AP33: =AM33+AO33 -> #VALUE! | AQ33: =IF(AN33="","",AP33/2) | AR33: - | AS33: - | AT33: - | AU33: - | AV33: - | AW33: - | AX33: - | BF33: =IF(BE33="","",BE33/2.14) | BL33: =IF(BK33="","",IF(AND(BJ33>400,BK33>1),"No Procede",IF(BK33<1,"",BI33-BK33-(BJ33/5)))) | BM33: =IF(BK33="","",IF(AND(BJ33>400,BK33>1),"NO PROCEDE",IF(BK33="","",BJ33/5))) | BS33: =IF(BQ33="","",SUM(BQ33:BR33)) | BV33: =IF(OR(BT33="",BU33=""),"",ROUND(BT33-BU33,1)) | BW33: =IF(OR(BT33="",BU33=""),"",ROUND(BU33/BV33,1)) | CO33: - | CP33: - | CQ33: - | CR33: -
A34: 32 | B34: 32 | G34: =CONCATENATE(D34," ",E34," ",F34) | P34: 46156 | AI34: =SUM(AA34:AH34) -> 0 | AM34: - | AO34: =AN34/2 -> 0 | AP34: =AM34+AO34 -> #VALUE! | AQ34: =IF(AN34="","",AP34/2) | AR34: - | AS34: - | AT34: - | AU34: - | AV34: - | AW34: - | AX34: - | BF34: =IF(BE34="","",BE34/2.14) | BL34: =IF(BK34="","",IF(AND(BJ34>400,BK34>1),"No Procede",IF(BK34<1,"",BI34-BK34-(BJ34/5)))) | BM34: =IF(BK34="","",IF(AND(BJ34>400,BK34>1),"NO PROCEDE",IF(BK34="","",BJ34/5))) | BS34: =IF(BQ34="","",SUM(BQ34:BR34)) | BV34: =IF(OR(BT34="",BU34=""),"",ROUND(BT34-BU34,1)) | BW34: =IF(OR(BT34="",BU34=""),"",ROUND(BU34/BV34,1)) | CO34: - | CP34: - | CQ34: - | CR34: -
A35: 33 | B35: 33 | G35: =CONCATENATE(D35," ",E35," ",F35) | P35: 46156 | AI35: =SUM(AA35:AH35) -> 0 | AM35: - | AO35: =AN35/2 -> 0 | AP35: =AM35+AO35 -> #VALUE! | AQ35: =IF(AN35="","",AP35/2) | AR35: - | AS35: - | AT35: - | AU35: - | AV35: - | AW35: - | AX35: - | BF35: =IF(BE35="","",BE35/2.14) | BL35: =IF(BK35="","",IF(AND(BJ35>400,BK35>1),"No Procede",IF(BK35<1,"",BI35-BK35-(BJ35/5)))) | BM35: =IF(BK35="","",IF(AND(BJ35>400,BK35>1),"NO PROCEDE",IF(BK35="","",BJ35/5))) | BS35: =IF(BQ35="","",SUM(BQ35:BR35)) | BV35: =IF(OR(BT35="",BU35=""),"",ROUND(BT35-BU35,1)) | BW35: =IF(OR(BT35="",BU35=""),"",ROUND(BU35/BV35,1)) | CO35: - | CP35: - | CQ35: - | CR35: -
A36: 34 | B36: 34 | G36: =CONCATENATE(D36," ",E36," ",F36) | P36: 46156 | AI36: =SUM(AA36:AH36) -> 0 | AM36: - | AO36: =AN36/2 -> 0 | AP36: =AM36+AO36 -> #VALUE! | AQ36: =IF(AN36="","",AP36/2) | AR36: - | AS36: - | AT36: - | AU36: - | AV36: - | AW36: - | AX36: - | BF36: =IF(BE36="","",BE36/2.14) | BL36: =IF(BK36="","",IF(AND(BJ36>400,BK36>1),"No Procede",IF(BK36<1,"",BI36-BK36-(BJ36/5)))) | BM36: =IF(BK36="","",IF(AND(BJ36>400,BK36>1),"NO PROCEDE",IF(BK36="","",BJ36/5))) | BS36: =IF(BQ36="","",SUM(BQ36:BR36)) | BV36: =IF(OR(BT36="",BU36=""),"",ROUND(BT36-BU36,1)) | BW36: =IF(OR(BT36="",BU36=""),"",ROUND(BU36/BV36,1)) | CO36: - | CP36: - | CQ36: - | CR36: -
A37: 35 | B37: 35 | G37: =CONCATENATE(D37," ",E37," ",F37) | P37: 46156 | AI37: =SUM(AA37:AH37) -> 0 | AM37: - | AO37: =AN37/2 -> 0 | AP37: =AM37+AO37 -> #VALUE! | AQ37: =IF(AN37="","",AP37/2) | AR37: - | AS37: - | AT37: - | AU37: - | AV37: - | AW37: - | AX37: - | BF37: =IF(BE37="","",BE37/2.14) | BL37: =IF(BK37="","",IF(AND(BJ37>400,BK37>1),"No Procede",IF(BK37<1,"",BI37-BK37-(BJ37/5)))) | BM37: =IF(BK37="","",IF(AND(BJ37>400,BK37>1),"NO PROCEDE",IF(BK37="","",BJ37/5))) | BS37: =IF(BQ37="","",SUM(BQ37:BR37)) | BV37: =IF(OR(BT37="",BU37=""),"",ROUND(BT37-BU37,1)) | BW37: =IF(OR(BT37="",BU37=""),"",ROUND(BU37/BV37,1)) | CO37: - | CP37: - | CQ37: - | CR37: -
A38: 36 | B38: 36 | G38: =CONCATENATE(D38," ",E38," ",F38) | P38: 46156 | AI38: =SUM(AA38:AH38) -> 0 | AM38: - | AO38: =AN38/2 -> 0 | AP38: =AM38+AO38 -> #VALUE! | AQ38: =IF(AN38="","",AP38/2) | AR38: - | AS38: - | AT38: - | AU38: - | AV38: - | AW38: - | AX38: - | BF38: =IF(BE38="","",BE38/2.14) | BL38: =IF(BK38="","",IF(AND(BJ38>400,BK38>1),"No Procede",IF(BK38<1,"",BI38-BK38-(BJ38/5)))) | BM38: =IF(BK38="","",IF(AND(BJ38>400,BK38>1),"NO PROCEDE",IF(BK38="","",BJ38/5))) | BS38: =IF(BQ38="","",SUM(BQ38:BR38)) | BV38: =IF(OR(BT38="",BU38=""),"",ROUND(BT38-BU38,1)) | BW38: =IF(OR(BT38="",BU38=""),"",ROUND(BU38/BV38,1)) | CO38: - | CP38: - | CQ38: - | CR38: -
A39: 37 | B39: 37 | G39: =CONCATENATE(D39," ",E39," ",F39) | P39: 46156 | AI39: =SUM(AA39:AH39) -> 0 | AM39: - | AO39: =AN39/2 -> 0 | AP39: =AM39+AO39 -> #VALUE! | AQ39: =IF(AN39="","",AP39/2) | AR39: - | AS39: - | AT39: - | AU39: - | AV39: - | AW39: - | AX39: - | BF39: =IF(BE39="","",BE39/2.14) | BL39: =IF(BK39="","",IF(AND(BJ39>400,BK39>1),"No Procede",IF(BK39<1,"",BI39-BK39-(BJ39/5)))) | BM39: =IF(BK39="","",IF(AND(BJ39>400,BK39>1),"NO PROCEDE",IF(BK39="","",BJ39/5))) | BS39: =IF(BQ39="","",SUM(BQ39:BR39)) | BV39: =IF(OR(BT39="",BU39=""),"",ROUND(BT39-BU39,1)) | BW39: =IF(OR(BT39="",BU39=""),"",ROUND(BU39/BV39,1)) | CO39: - | CP39: - | CQ39: - | CR39: -
A40: 38 | B40: 38 | G40: =CONCATENATE(D40," ",E40," ",F40) | P40: 46156 | AI40: =SUM(AA40:AH40) -> 0 | AM40: - | AO40: =AN40/2 -> 0 | AP40: =AM40+AO40 -> #VALUE! | AQ40: =IF(AN40="","",AP40/2) | AR40: - | AS40: - | AT40: - | AU40: - | AV40: - | AW40: - | AX40: - | BF40: =IF(BE40="","",BE40/2.14) | BL40: =IF(BK40="","",IF(AND(BJ40>400,BK40>1),"No Procede",IF(BK40<1,"",BI40-BK40-(BJ40/5)))) | BM40: =IF(BK40="","",IF(AND(BJ40>400,BK40>1),"NO PROCEDE",IF(BK40="","",BJ40/5))) | BS40: =IF(BQ40="","",SUM(BQ40:BR40)) | BV40: =IF(OR(BT40="",BU40=""),"",ROUND(BT40-BU40,1)) | BW40: =IF(OR(BT40="",BU40=""),"",ROUND(BU40/BV40,1)) | CO40: - | CP40: - | CQ40: - | CR40: -
...

Sheet SNIS NO TOCAR
A1: NUMERO DE PACIENTES ATENDIDOS | H1: TOTAL | I1: M | J1: F | K1: EMB | M1: HIV
A2: RUTINA | B2: =B5-B3 -> 12 | D2: CIMFA | E2: =COUNTIF(DATOS!L3:L300,"CIMFA EL ALTO") -> 3 | G2: HIV | H2: =COUNTA(DATOS!CI3:CI300) -> 1 | I2: =COUNTIFS(DATOS!CI3:CI300,"NO REACTIVO",DATOS!I3:I300,"MASCULINO") -> 0 | J2: =COUNTIFS(DATOS!CI3:CI300,"NO REACTIVO",DATOS!I3:I300,"FEMENINO") -> 1 | M2: GENERAL | O2: =COUNTA(DATOS!CI3:CI300) -> 1
A3: EMERGENCIA | B3: =COUNTA(DATOS!C3:C300) -> 5 | D3: PAISE | E3: =COUNTIF(DATOS!L3:L300,"PAISE EL ALTO") -> 13 | M3: M. EMB | O3: =COUNTIFS(DATOS!CI3:CI300,"NO REACTIVO",DATOS!R3:R300,"EMB") -> 0
D4: OTROS | E4: =E5-E3-E2 -> 1
A5: TOTAL | B5: =COUNTA(DATOS!I3:I300) -> 17 | D5: TOTAL | E5: =COUNTA(DATOS!I3:I300) -> 17 | H5: HTO | I5: GB | J5: DIF | K5: PLAQ | L5: GS | M5: VES | N5: RET | O5: TS | P5: TC | Q5: TP
